Workbook

Sheet ESPANOL
E7: CALCULO DE NOTAS | AO7: Calificacion Final | AP7: % DE ASISTENCIA ANUAL | AR7: CALIFICACION COMPLETIVA | AV7: CALIFICACION EXTRAORDINARIA | AZ7: EVALUACION ESPECIAL | BB7: SITUACIONFINAL EN LA ASIGNATURA
A9: NO | B9: ID | C9: NOMBRES | D9: APELLIDOS | E9: CE - LE1 | M9: CE - LE2, LE3 | U9: CE - LE4, LE6 | AC9: CE - LE5, LE7 | AK9: PCP 1 | AL9: PCP 2 | AM9: PCP 3 | AN9: PCP 4 | AR9: 50% C.F | AS9: C.E.C. | AT9: 50% C.E.C. | AU9: C.C.F | AV9: 30% C.F. | AW9: C.E.EX | AX9: 70% C.E.EX | AY9: C.EX.F | AZ9: C.F. | BA9: C.E. | BB9: A | BC9: R
E10: P1 | F10: RP1 | G10: P2 | H10: RP2 | I10: P3 | J10: RP3 | K10: P4 | L10: RP4 | M10: P1 | N10: RP1 | O10: P2 | P10: RP2 | Q10: P3 | R10: RP3 | S10: P4 | T10: RP4 | U10: P1 | V10: RP1 | W10: P2 | X10: RP3 | Y10: P3 | Z10: RP4 | AA10: P4 | AB10: RP4 | AC10: P1 | AD10: RP1 | AE10: P2 | AF10: RP3 | AG10: P3 | AH10: RP4 | AI10: P4 | AJ10: RP4 | BE10: P1 | BF10: P2 | BG10: P3 | BH10: P4 | BI10: C.F
A11: 1 | B11: 4A-D-01 | C11: ALEXANDRA | D11: JIMENEZ RODRIGUEZ | AK11: =SUMIF(E11:E11, ">=70") / 4 +SUMIF(G11:G11, ">=70") / 4 +SUMIF(I11:I11, ">=70") / 4 +SUMIF(K11:K11, ">=70") / 4 + SUMIF(F11:F11, ">1") / 4 + SUMIF(H11:H11, ">1") / 4 + SUMIF(J11:J11, ">1") / 4 + SUMIF(L11:L11, ">1") / 4 -> 0 | AL11: =SUMIF(M11:M11, ">=70") / 4 +SUMIF(O11:O11, ">=70") / 4 +SUMIF(Q11:Q11, ">=70") / 4 +SUMIF(S11:S11, ">=70") / 4 + SUMIF(N11:N11, ">1") / 4 + SUMIF(P11:P11, ">1") / 4 + SUMIF(R11:R11, ">1") / 4 + SUMIF(T11:T11, ">1") / 4 -> 0 | AM11: =SUMIF(U11:U11, ">=70") / 4 +SUMIF(W11:W11, ">=70") / 4 +SUMIF(Y11:Y11, ">=70") / 4 +SUMIF(AA11:AA11, ">=70") / 4 + SUMIF(V11:V11, ">1") / 4 + SUMIF(X11:X11, ">1") / 4 + SUMIF(Z11:Z11, ">1") / 4 + SUMIF(AB11:AB11, ">1") / 4 -> 0 | AN11: =SUMIF(AC11:AC11, ">=70") / 4 +SUMIF(AE11:AE11, ">=70") / 4 +SUMIF(AG11:AG11, ">=70") / 4 +SUMIF(AI11:AI11, ">=70") / 4 + SUMIF(AD11:AD11, ">1") / 4 + SUMIF(AF11:AF11, ">1") / 4 + SUMIF(AH11:AH11, ">1") / 4 + SUMIF(AJ11:AJ11, ">1") / 4 -> 0 | AO11: =AVERAGE(AK11:AN11) -> 0 | AR11: =IF(AO11<70, AO11*0.5, "") -> 0 | AT11: =AS11*50% -> 0 | AU11: =IF(AS11<>"", IF(AR11="","",AR11+AT11), "") | AV11: =IF(AU11 < 70, AR11*30%, "") | AX11: =AW11*70% -> 0 | AY11: =IF(AW11<>"", IF(AV11="", "", AV11+AX11), "") | AZ11: =IF(AND(AU11<70, AY11<70), AO11, "") | BB11: =IF(AW11<>"", IF(AY11>=70, AY11, IF(AZ11+BA11>=70, AZ11+BA11, "")), IF(AS11<>"", IF(AU11>=70, AU11, ""), IF(AO11>=70, AO11, ""))) | BC11: =IF(AW11<>"", IF(AY11<70, IF(AZ11+BA11<70, AZ11+BA11, ""), ""), IF(AS11<>"", IF(AU11<70, AU11, ""), IF(AO11<70, AO11, ""))) -> 0 | BE11: =SUMIF(E11:E11, ">=70") / 4 +SUMIF(F11:F11, ">1") / 4 +SUMIF(M11:M11, ">=70") / 4 +SUMIF(N11:N11, ">1") / 4 + SUMIF(U11:U11, ">=70") / 4 + SUMIF(V11:V11, ">1") / 4 + SUMIF(AC11:AC11, ">=70") / 4 + SUMIF(AD11:AD11, ">1") / 4 -> 0 | BF11: =SUMIF(G11:G11, ">=70") / 4 +SUMIF(H11:H11, ">1") / 4 +SUMIF(O11:O11, ">=70") / 4 +SUMIF(P11:P11, ">1") / 4 + SUMIF(W11:W11, ">=70") / 4 + SUMIF(X11:X11, ">1") / 4 + SUMIF(AE11:AE11, ">=70") / 4 + SUMIF(AF11:AF11, ">1") / 4 -> 0 | BG11: =SUMIF(I11:I11, ">=70") / 4 +SUMIF(J11:J11, ">1") / 4 +SUMIF(Q11:Q11, ">=70") / 4 +SUMIF(R11:R11, ">1") / 4 + SUMIF(Y11:Y11, ">=70") / 4 + SUMIF(Z11:Z11, ">1") / 4 + SUMIF(AG11:AG11, ">=70") / 4 + SUMIF(AH11:AH11, ">1") / 4 -> 0 | BH11: =SUMIF(K11:K11, ">=70") / 4 +SUMIF(L11:L11, ">1") / 4 +SUMIF(S11:S11, ">=70") / 4 +SUMIF(T11:T11, ">1") / 4 + SUMIF(AA11:AA11, ">=70") / 4 + SUMIF(AB11:AB11, ">1") / 4 + SUMIF(AI11:AI11, ">=70") / 4 + SUMIF(AJ11:AJ11, ">1") / 4 -> 0 | BI11: =AVERAGE(BE11:BH11) -> 0
A12: 2 | B12: 4A-D-02 | C12: ANDERSON | D12: CEBALLOS DE LA CRUZ | AK12: =SUMIF(E12:E12, ">=70") / 4 +SUMIF(G12:G12, ">=70") / 4 +SUMIF(I12:I12, ">=70") / 4 +SUMIF(K12:K12, ">=70") / 4 + SUMIF(F12:F12, ">1") / 4 + SUMIF(H12:H12, ">1") / 4 + SUMIF(J12:J12, ">1") / 4 + SUMIF(L12:L12, ">1") / 4 -> 0 | AL12: =SUMIF(M12:M12, ">=70") / 4 +SUMIF(O12:O12, ">=70") / 4 +SUMIF(Q12:Q12, ">=70") / 4 +SUMIF(S12:S12, ">=70") / 4 + SUMIF(N12:N12, ">1") / 4 + SUMIF(P12:P12, ">1") / 4 + SUMIF(R12:R12, ">1") / 4 + SUMIF(T12:T12, ">1") / 4 -> 0 | AM12: =SUMIF(U12:U12, ">=70") / 4 +SUMIF(W12:W12, ">=70") / 4 +SUMIF(Y12:Y12, ">=70") / 4 +SUMIF(AA12:AA12, ">=70") / 4 + SUMIF(V12:V12, ">1") / 4 + SUMIF(X12:X12, ">1") / 4 + SUMIF(Z12:Z12, ">1") / 4 + SUMIF(AB12:AB12, ">1") / 4 -> 0 | AN12: =SUMIF(AC12:AC12, ">=65") / 4 +SUMIF(AE12:AE12, ">=65") / 4 +SUMIF(AG12:AG12, ">=65") / 4 +SUMIF(AI12:AI12, ">=65") / 4 + SUMIF(AD12:AD12, ">1") / 4 + SUMIF(AF12:AF12, ">1") / 4 + SUMIF(AH12:AH12, ">1") / 4 + SUMIF(AJ12:AJ12, ">1") / 4 -> 0 | AO12: =AVERAGE(AK12:AN12) -> 0 | AR12: =IF(AO12<70, AO12*0.5, "") -> 0 | AT12: =AS12*50% -> 0 | AU12: =IF(AS12<>"", IF(AR12="","",AR12+AT12), "") | AV12: =IF(AU12 < 70, AR12*30%, "") | AX12: =AW12*70% -> 0 | AY12: =IF(AW12<>"", IF(AV12="", "", AV12+AX12), "") | AZ12: =IF(AND(AU12<70, AY12<70), AO12, "") | BB12: =IF(AW12<>"", IF(AY12>=70, AY12, IF(AZ12+BA12>=70, AZ12+BA12, "")), IF(AS12<>"", IF(AU12>=70, AU12, ""), IF(AO12>=70, AO12, ""))) | BC12: =IF(AW12<>"", IF(AY12<70, IF(AZ12+BA12<70, AZ12+BA12, ""), ""), IF(AS12<>"", IF(AU12<70, AU12, ""), IF(AO12<70, AO12, ""))) -> 0 | BE12: =SUMIF(E12:E12, ">=70") / 4 +SUMIF(F12:F12, ">1") / 4 +SUMIF(M12:M12, ">=70") / 4 +SUMIF(N12:N12, ">1") / 4 + SUMIF(U12:U12, ">=70") / 4 + SUMIF(V12:V12, ">1") / 4 + SUMIF(AC12:AC12, ">=70") / 4 + SUMIF(AD12:AD12, ">1") / 4 -> 0 | BF12: =SUMIF(G12:G12, ">=70") / 4 +SUMIF(H12:H12, ">1") / 4 +SUMIF(O12:O12, ">=70") / 4 +SUMIF(P12:P12, ">1") / 4 + SUMIF(W12:W12, ">=70") / 4 + SUMIF(X12:X12, ">1") / 4 + SUMIF(AE12:AE12, ">=70") / 4 + SUMIF(AF12:AF12, ">1") / 4 -> 0 | BG12: =SUMIF(I12:I12, ">=70") / 4 +SUMIF(J12:J12, ">1") / 4 +SUMIF(Q12:Q12, ">=70") / 4 +SUMIF(R12:R12, ">1") / 4 + SUMIF(Y12:Y12, ">=70") / 4 + SUMIF(Z12:Z12, ">1") / 4 + SUMIF(AG12:AG12, ">=70") / 4 + SUMIF(AH12:AH12, ">1") / 4 -> 0 | BH12: =SUMIF(K12:K12, ">=70") / 4 +SUMIF(L12:L12, ">1") / 4 +SUMIF(S12:S12, ">=70") / 4 +SUMIF(T12:T12, ">1") / 4 + SUMIF(AA12:AA12, ">=70") / 4 + SUMIF(AB12:AB12, ">1") / 4 + SUMIF(AI12:AI12, ">=70") / 4 + SUMIF(AJ12:AJ12, ">1") / 4 -> 0 | BI12: =AVERAGE(BE12:BH12) -> 0
A13: 3 | B13: 4A-D-03 | C13: ANGELINA | D13: PEREZ MEDINA | AK13: =SUMIF(E13:E13, ">=70") / 4 +SUMIF(G13:G13, ">=70") / 4 +SUMIF(I13:I13, ">=70") / 4 +SUMIF(K13:K13, ">=70") / 4 + SUMIF(F13:F13, ">1") / 4 + SUMIF(H13:H13, ">1") / 4 + SUMIF(J13:J13, ">1") / 4 + SUMIF(L13:L13, ">1") / 4 -> 0 | AL13: =SUMIF(M13:M13, ">=70") / 4 +SUMIF(O13:O13, ">=70") / 4 +SUMIF(Q13:Q13, ">=70") / 4 +SUMIF(S13:S13, ">=70") / 4 + SUMIF(N13:N13, ">1") / 4 + SUMIF(P13:P13, ">1") / 4 + SUMIF(R13:R13, ">1") / 4 + SUMIF(T13:T13, ">1") / 4 -> 0 | AM13: =SUMIF(U13:U13, ">=70") / 4 +SUMIF(W13:W13, ">=70") / 4 +SUMIF(Y13:Y13, ">=70") / 4 +SUMIF(AA13:AA13, ">=70") / 4 + SUMIF(V13:V13, ">1") / 4 + SUMIF(X13:X13, ">1") / 4 + SUMIF(Z13:Z13, ">1") / 4 + SUMIF(AB13:AB13, ">1") / 4 -> 0 | AN13: =SUMIF(AC13:AC13, ">=65") / 4 +SUMIF(AE13:AE13, ">=65") / 4 +SUMIF(AG13:AG13, ">=65") / 4 +SUMIF(AI13:AI13, ">=65") / 4 + SUMIF(AD13:AD13, ">1") / 4 + SUMIF(AF13:AF13, ">1") / 4 + SUMIF(AH13:AH13, ">1") / 4 + SUMIF(AJ13:AJ13, ">1") / 4 -> 0 | AO13: =AVERAGE(AK13:AN13) -> 0 | AR13: =IF(AO13<70, AO13*0.5, "") -> 0 | AT13: =AS13*50% -> 0 | AU13: =IF(AS13<>"", IF(AR13="","",AR13+AT13), "") | AV13: =IF(AU13 < 70, AR13*30%, "") | AX13: =AW13*70% -> 0 | AY13: =IF(AW13<>"", IF(AV13="", "", AV13+AX13), "") | AZ13: =IF(AND(AU13<70, AY13<70), AO13, "") | BB13: =IF(AW13<>"", IF(AY13>=70, AY13, IF(AZ13+BA13>=70, AZ13+BA13, "")), IF(AS13<>"", IF(AU13>=70, AU13, ""), IF(AO13>=70, AO13, ""))) | BC13: =IF(AW13<>"", IF(AY13<70, IF(AZ13+BA13<70, AZ13+BA13, ""), ""), IF(AS13<>"", IF(AU13<70, AU13, ""), IF(AO13<70, AO13, ""))) -> 0 | BE13: =SUMIF(E13:E13, ">=70") / 4 +SUMIF(F13:F13, ">1") / 4 +SUMIF(M13:M13, ">=70") / 4 +SUMIF(N13:N13, ">1") / 4 + SUMIF(U13:U13, ">=70") / 4 + SUMIF(V13:V13, ">1") / 4 + SUMIF(AC13:AC13, ">=70") / 4 + SUMIF(AD13:AD13, ">1") / 4 -> 0 | BF13: =SUMIF(G13:G13, ">=70") / 4 +SUMIF(H13:H13, ">1") / 4 +SUMIF(O13:O13, ">=70") / 4 +SUMIF(P13:P13, ">1") / 4 + SUMIF(W13:W13, ">=70") / 4 + SUMIF(X13:X13, ">1") / 4 + SUMIF(AE13:AE13, ">=70") / 4 + SUMIF(AF13:AF13, ">1") / 4 -> 0 | BG13: =SUMIF(I13:I13, ">=70") / 4 +SUMIF(J13:J13, ">1") / 4 +SUMIF(Q13:Q13, ">=70") / 4 +SUMIF(R13:R13, ">1") / 4 + SUMIF(Y13:Y13, ">=70") / 4 + SUMIF(Z13:Z13, ">1") / 4 + SUMIF(AG13:AG13, ">=70") / 4 + SUMIF(AH13:AH13, ">1") / 4 -> 0 | BH13: =SUMIF(K13:K13, ">=70") / 4 +SUMIF(L13:L13, ">1") / 4 +SUMIF(S13:S13, ">=70") / 4 +SUMIF(T13:T13, ">1") / 4 + SUMIF(AA13:AA13, ">=70") / 4 + SUMIF(AB13:AB13, ">1") / 4 + SUMIF(AI13:AI13, ">=70") / 4 + SUMIF(AJ13:AJ13, ">1") / 4 -> 0 | BI13: =AVERAGE(BE13:BH13) -> 0
A14: 4 | B14: 4A-D-04 | C14: ARIEL ALFONSO | D14: GALVEZ CESPEDES | AK14: =SUMIF(E14:E14, ">=70") / 4 +SUMIF(G14:G14, ">=70") / 4 +SUMIF(I14:I14, ">=70") / 4 +SUMIF(K14:K14, ">=70") / 4 + SUMIF(F14:F14, ">1") / 4 + SUMIF(H14:H14, ">1") / 4 + SUMIF(J14:J14, ">1") / 4 + SUMIF(L14:L14, ">1") / 4 -> 0 | AL14: =SUMIF(M14:M14, ">=70") / 4 +SUMIF(O14:O14, ">=70") / 4 +SUMIF(Q14:Q14, ">=70") / 4 +SUMIF(S14:S14, ">=70") / 4 + SUMIF(N14:N14, ">1") / 4 + SUMIF(P14:P14, ">1") / 4 + SUMIF(R14:R14, ">1") / 4 + SUMIF(T14:T14, ">1") / 4 -> 0 | AM14: =SUMIF(U14:U14, ">=70") / 4 +SUMIF(W14:W14, ">=70") / 4 +SUMIF(Y14:Y14, ">=70") / 4 +SUMIF(AA14:AA14, ">=70") / 4 + SUMIF(V14:V14, ">1") / 4 + SUMIF(X14:X14, ">1") / 4 + SUMIF(Z14:Z14, ">1") / 4 + SUMIF(AB14:AB14, ">1") / 4 -> 0 | AN14: =SUMIF(AC14:AC14, ">=65") / 4 +SUMIF(AE14:AE14, ">=65") / 4 +SUMIF(AG14:AG14, ">=65") / 4 +SUMIF(AI14:AI14, ">=65") / 4 + SUMIF(AD14:AD14, ">1") / 4 + SUMIF(AF14:AF14, ">1") / 4 + SUMIF(AH14:AH14, ">1") / 4 + SUMIF(AJ14:AJ14, ">1") / 4 -> 0 | AO14: =AVERAGE(AK14:AN14) -> 0 | AR14: =IF(AO14<70, AO14*0.5, "") -> 0 | AT14: =AS14*50% -> 0 | AU14: =IF(AS14<>"", IF(AR14="","",AR14+AT14), "") | AV14: =IF(AU14 < 70, AR14*30%, "") | AX14: =AW14*70% -> 0 | AY14: =IF(AW14<>"", IF(AV14="", "", AV14+AX14), "") | AZ14: =IF(AND(AU14<70, AY14<70), AO14, "") | BB14: =IF(AW14<>"", IF(AY14>=70, AY14, IF(AZ14+BA14>=70, AZ14+BA14, "")), IF(AS14<>"", IF(AU14>=70, AU14, ""), IF(AO14>=70, AO14, ""))) | BC14: =IF(AW14<>"", IF(AY14<70, IF(AZ14+BA14<70, AZ14+BA14, ""), ""), IF(AS14<>"", IF(AU14<70, AU14, ""), IF(AO14<70, AO14, ""))) -> 0 | BE14: =SUMIF(E14:E14, ">=70") / 4 +SUMIF(F14:F14, ">1") / 4 +SUMIF(M14:M14, ">=70") / 4 +SUMIF(N14:N14, ">1") / 4 + SUMIF(U14:U14, ">=70") / 4 + SUMIF(V14:V14, ">1") / 4 + SUMIF(AC14:AC14, ">=70") / 4 + SUMIF(AD14:AD14, ">1") / 4 -> 0 | BF14: =SUMIF(G14:G14, ">=70") / 4 +SUMIF(H14:H14, ">1") / 4 +SUMIF(O14:O14, ">=70") / 4 +SUMIF(P14:P14, ">1") / 4 + SUMIF(W14:W14, ">=70") / 4 + SUMIF(X14:X14, ">1") / 4 + SUMIF(AE14:AE14, ">=70") / 4 + SUMIF(AF14:AF14, ">1") / 4 -> 0 | BG14: =SUMIF(I14:I14, ">=70") / 4 +SUMIF(J14:J14, ">1") / 4 +SUMIF(Q14:Q14, ">=70") / 4 +SUMIF(R14:R14, ">1") / 4 + SUMIF(Y14:Y14, ">=70") / 4 + SUMIF(Z14:Z14, ">1") / 4 + SUMIF(AG14:AG14, ">=70") / 4 + SUMIF(AH14:AH14, ">1") / 4 -> 0 | BH14: =SUMIF(K14:K14, ">=70") / 4 +SUMIF(L14:L14, ">1") / 4 +SUMIF(S14:S14, ">=70") / 4 +SUMIF(T14:T14, ">1") / 4 + SUMIF(AA14:AA14, ">=70") / 4 + SUMIF(AB14:AB14, ">1") / 4 + SUMIF(AI14:AI14, ">=70") / 4 + SUMIF(AJ14:AJ14, ">1") / 4 -> 0 | BI14: =AVERAGE(BE14:BH14) -> 0
A15: 5 | B15: 4A-D-05 | C15: CARLOS DAVID | D15: ARRENDER RODRIGUEZ | AK15: =SUMIF(E15:E15, ">=70") / 4 +SUMIF(G15:G15, ">=70") / 4 +SUMIF(I15:I15, ">=70") / 4 +SUMIF(K15:K15, ">=70") / 4 + SUMIF(F15:F15, ">1") / 4 + SUMIF(H15:H15, ">1") / 4 + SUMIF(J15:J15, ">1") / 4 + SUMIF(L15:L15, ">1") / 4 -> 0 | AL15: =SUMIF(M15:M15, ">=70") / 4 +SUMIF(O15:O15, ">=70") / 4 +SUMIF(Q15:Q15, ">=70") / 4 +SUMIF(S15:S15, ">=70") / 4 + SUMIF(N15:N15, ">1") / 4 + SUMIF(P15:P15, ">1") / 4 + SUMIF(R15:R15, ">1") / 4 + SUMIF(T15:T15, ">1") / 4 -> 0 | AM15: =SUMIF(U15:U15, ">=70") / 4 +SUMIF(W15:W15, ">=70") / 4 +SUMIF(Y15:Y15, ">=70") / 4 +SUMIF(AA15:AA15, ">=70") / 4 + SUMIF(V15:V15, ">1") / 4 + SUMIF(X15:X15, ">1") / 4 + SUMIF(Z15:Z15, ">1") / 4 + SUMIF(AB15:AB15, ">1") / 4 -> 0 | AN15: =SUMIF(AC15:AC15, ">=65") / 4 +SUMIF(AE15:AE15, ">=65") / 4 +SUMIF(AG15:AG15, ">=65") / 4 +SUMIF(AI15:AI15, ">=65") / 4 + SUMIF(AD15:AD15, ">1") / 4 + SUMIF(AF15:AF15, ">1") / 4 + SUMIF(AH15:AH15, ">1") / 4 + SUMIF(AJ15:AJ15, ">1") / 4 -> 0 | AO15: =AVERAGE(AK15:AN15) -> 0 | AR15: =IF(AO15<70, AO15*0.5, "") -> 0 | AT15: =AS15*50% -> 0 | AU15: =IF(AS15<>"", IF(AR15="","",AR15+AT15), "") | AV15: =IF(AU15 < 70, AR15*30%, "") | AX15: =AW15*70% -> 0 | AY15: =IF(AW15<>"", IF(AV15="", "", AV15+AX15), "") | AZ15: =IF(AND(AU15<70, AY15<70), AO15, "") | BB15: =IF(AW15<>"", IF(AY15>=70, AY15, IF(AZ15+BA15>=70, AZ15+BA15, "")), IF(AS15<>"", IF(AU15>=70, AU15, ""), IF(AO15>=70, AO15, ""))) | BC15: =IF(AW15<>"", IF(AY15<70, IF(AZ15+BA15<70, AZ15+BA15, ""), ""), IF(AS15<>"", IF(AU15<70, AU15, ""), IF(AO15<70, AO15, ""))) -> 0 | BE15: =SUMIF(E15:E15, ">=70") / 4 +SUMIF(F15:F15, ">1") / 4 +SUMIF(M15:M15, ">=70") / 4 +SUMIF(N15:N15, ">1") / 4 + SUMIF(U15:U15, ">=70") / 4 + SUMIF(V15:V15, ">1") / 4 + SUMIF(AC15:AC15, ">=70") / 4 + SUMIF(AD15:AD15, ">1") / 4 -> 0 | BF15: =SUMIF(G15:G15, ">=70") / 4 +SUMIF(H15:H15, ">1") / 4 +SUMIF(O15:O15, ">=70") / 4 +SUMIF(P15:P15, ">1") / 4 + SUMIF(W15:W15, ">=70") / 4 + SUMIF(X15:X15, ">1") / 4 + SUMIF(AE15:AE15, ">=70") / 4 + SUMIF(AF15:AF15, ">1") / 4 -> 0 | BG15: =SUMIF(I15:I15, ">=70") / 4 +SUMIF(J15:J15, ">1") / 4 +SUMIF(Q15:Q15, ">=70") / 4 +SUMIF(R15:R15, ">1") / 4 + SUMIF(Y15:Y15, ">=70") / 4 + SUMIF(Z15:Z15, ">1") / 4 + SUMIF(AG15:AG15, ">=70") / 4 + SUMIF(AH15:AH15, ">1") / 4 -> 0 | BH15: =SUMIF(K15:K15, ">=70") / 4 +SUMIF(L15:L15, ">1") / 4 +SUMIF(S15:S15, ">=70") / 4 +SUMIF(T15:T15, ">1") / 4 + SUMIF(AA15:AA15, ">=70") / 4 + SUMIF(AB15:AB15, ">1") / 4 + SUMIF(AI15:AI15, ">=70") / 4 + SUMIF(AJ15:AJ15, ">1") / 4 -> 0 | BI15: =AVERAGE(BE15:BH15) -> 0
A16: 6 | B16: 4A-D-06 | C16: CLARENCE WILLIANS | D16: FERNANDEZ FERNANDEZ | AK16: =SUMIF(E16:E16, ">=70") / 4 +SUMIF(G16:G16, ">=70") / 4 +SUMIF(I16:I16, ">=70") / 4 +SUMIF(K16:K16, ">=70") / 4 + SUMIF(F16:F16, ">1") / 4 + SUMIF(H16:H16, ">1") / 4 + SUMIF(J16:J16, ">1") / 4 + SUMIF(L16:L16, ">1") / 4 -> 0 | AL16: =SUMIF(M16:M16, ">=70") / 4 +SUMIF(O16:O16, ">=70") / 4 +SUMIF(Q16:Q16, ">=70") / 4 +SUMIF(S16:S16, ">=70") / 4 + SUMIF(N16:N16, ">1") / 4 + SUMIF(P16:P16, ">1") / 4 + SUMIF(R16:R16, ">1") / 4 + SUMIF(T16:T16, ">1") / 4 -> 0 | AM16: =SUMIF(U16:U16, ">=70") / 4 +SUMIF(W16:W16, ">=70") / 4 +SUMIF(Y16:Y16, ">=70") / 4 +SUMIF(AA16:AA16, ">=70") / 4 + SUMIF(V16:V16, ">1") / 4 + SUMIF(X16:X16, ">1") / 4 + SUMIF(Z16:Z16, ">1") / 4 + SUMIF(AB16:AB16, ">1") / 4 -> 0 | AN16: =SUMIF(AC16:AC16, ">=65") / 4 +SUMIF(AE16:AE16, ">=65") / 4 +SUMIF(AG16:AG16, ">=65") / 4 +SUMIF(AI16:AI16, ">=65") / 4 + SUMIF(AD16:AD16, ">1") / 4 + SUMIF(AF16:AF16, ">1") / 4 + SUMIF(AH16:AH16, ">1") / 4 + SUMIF(AJ16:AJ16, ">1") / 4 -> 0 | AO16: =AVERAGE(AK16:AN16) -> 0 | AR16: =IF(AO16<70, AO16*0.5, "") -> 0 | AT16: =AS16*50% -> 0 | AU16: =IF(AS16<>"", IF(AR16="","",AR16+AT16), "") | AV16: =IF(AU16 < 70, AR16*30%, "") | AX16: =AW16*70% -> 0 | AY16: =IF(AW16<>"", IF(AV16="", "", AV16+AX16), "") | AZ16: =IF(AND(AU16<70, AY16<70), AO16, "") | BB16: =IF(AW16<>"", IF(AY16>=70, AY16, IF(AZ16+BA16>=70, AZ16+BA16, "")), IF(AS16<>"", IF(AU16>=70, AU16, ""), IF(AO16>=70, AO16, ""))) | BC16: =IF(AW16<>"", IF(AY16<70, IF(AZ16+BA16<70, AZ16+BA16, ""), ""), IF(AS16<>"", IF(AU16<70, AU16, ""), IF(AO16<70, AO16, ""))) -> 0 | BE16: =SUMIF(E16:E16, ">=70") / 4 +SUMIF(F16:F16, ">1") / 4 +SUMIF(M16:M16, ">=70") / 4 +SUMIF(N16:N16, ">1") / 4 + SUMIF(U16:U16, ">=70") / 4 + SUMIF(V16:V16, ">1") / 4 + SUMIF(AC16:AC16, ">=70") / 4 + SUMIF(AD16:AD16, ">1") / 4 -> 0 | BF16: =SUMIF(G16:G16, ">=70") / 4 +SUMIF(H16:H16, ">1") / 4 +SUMIF(O16:O16, ">=70") / 4 +SUMIF(P16:P16, ">1") / 4 + SUMIF(W16:W16, ">=70") / 4 + SUMIF(X16:X16, ">1") / 4 + SUMIF(AE16:AE16, ">=70") / 4 + SUMIF(AF16:AF16, ">1") / 4 -> 0 | BG16: =SUMIF(I16:I16, ">=70") / 4 +SUMIF(J16:J16, ">1") / 4 +SUMIF(Q16:Q16, ">=70") / 4 +SUMIF(R16:R16, ">1") / 4 + SUMIF(Y16:Y16, ">=70") / 4 + SUMIF(Z16:Z16, ">1") / 4 + SUMIF(AG16:AG16, ">=70") / 4 + SUMIF(AH16:AH16, ">1") / 4 -> 0 | BH16: =SUMIF(K16:K16, ">=70") / 4 +SUMIF(L16:L16, ">1") / 4 +SUMIF(S16:S16, ">=70") / 4 +SUMIF(T16:T16, ">1") / 4 + SUMIF(AA16:AA16, ">=70") / 4 + SUMIF(AB16:AB16, ">1") / 4 + SUMIF(AI16:AI16, ">=70") / 4 + SUMIF(AJ16:AJ16, ">1") / 4 -> 0 | BI16: =AVERAGE(BE16:BH16) -> 0
A17: 7 | B17: 4A-D-07 | C17: DARIEL RAFAEL | D17: LANTIGUA PEGUERO | AK17: =SUMIF(E17:E17, ">=70") / 4 +SUMIF(G17:G17, ">=70") / 4 +SUMIF(I17:I17, ">=70") / 4 +SUMIF(K17:K17, ">=70") / 4 + SUMIF(F17:F17, ">1") / 4 + SUMIF(H17:H17, ">1") / 4 + SUMIF(J17:J17, ">1") / 4 + SUMIF(L17:L17, ">1") / 4 -> 0 | AL17: =SUMIF(M17:M17, ">=70") / 4 +SUMIF(O17:O17, ">=70") / 4 +SUMIF(Q17:Q17, ">=70") / 4 +SUMIF(S17:S17, ">=70") / 4 + SUMIF(N17:N17, ">1") / 4 + SUMIF(P17:P17, ">1") / 4 + SUMIF(R17:R17, ">1") / 4 + SUMIF(T17:T17, ">1") / 4 -> 0 | AM17: =SUMIF(U17:U17, ">=70") / 4 +SUMIF(W17:W17, ">=70") / 4 +SUMIF(Y17:Y17, ">=70") / 4 +SUMIF(AA17:AA17, ">=70") / 4 + SUMIF(V17:V17, ">1") / 4 + SUMIF(X17:X17, ">1") / 4 + SUMIF(Z17:Z17, ">1") / 4 + SUMIF(AB17:AB17, ">1") / 4 -> 0 | AN17: =SUMIF(AC17:AC17, ">=65") / 4 +SUMIF(AE17:AE17, ">=65") / 4 +SUMIF(AG17:AG17, ">=65") / 4 +SUMIF(AI17:AI17, ">=65") / 4 + SUMIF(AD17:AD17, ">1") / 4 + SUMIF(AF17:AF17, ">1") / 4 + SUMIF(AH17:AH17, ">1") / 4 + SUMIF(AJ17:AJ17, ">1") / 4 -> 0 | AO17: =AVERAGE(AK17:AN17) -> 0 | AR17: =IF(AO17<70, AO17*0.5, "") -> 0 | AT17: =AS17*50% -> 0 | AU17: =IF(AS17<>"", IF(AR17="","",AR17+AT17), "") | AV17: =IF(AU17 < 70, AR17*30%, "") | AX17: =AW17*70% -> 0 | AY17: =IF(AW17<>"", IF(AV17="", "", AV17+AX17), "") | AZ17: =IF(AND(AU17<70, AY17<70), AO17, "") | BB17: =IF(AW17<>"", IF(AY17>=70, AY17, IF(AZ17+BA17>=70, AZ17+BA17, "")), IF(AS17<>"", IF(AU17>=70, AU17, ""), IF(AO17>=70, AO17, ""))) | BC17: =IF(AW17<>"", IF(AY17<70, IF(AZ17+BA17<70, AZ17+BA17, ""), ""), IF(AS17<>"", IF(AU17<70, AU17, ""), IF(AO17<70, AO17, ""))) -> 0 | BE17: =SUMIF(E17:E17, ">=70") / 4 +SUMIF(F17:F17, ">1") / 4 +SUMIF(M17:M17, ">=70") / 4 +SUMIF(N17:N17, ">1") / 4 + SUMIF(U17:U17, ">=70") / 4 + SUMIF(V17:V17, ">1") / 4 + SUMIF(AC17:AC17, ">=70") / 4 + SUMIF(AD17:AD17, ">1") / 4 -> 0 | BF17: =SUMIF(G17:G17, ">=70") / 4 +SUMIF(H17:H17, ">1") / 4 +SUMIF(O17:O17, ">=70") / 4 +SUMIF(P17:P17, ">1") / 4 + SUMIF(W17:W17, ">=70") / 4 + SUMIF(X17:X17, ">1") / 4 + SUMIF(AE17:AE17, ">=70") / 4 + SUMIF(AF17:AF17, ">1") / 4 -> 0 | BG17: =SUMIF(I17:I17, ">=70") / 4 +SUMIF(J17:J17, ">1") / 4 +SUMIF(Q17:Q17, ">=70") / 4 +SUMIF(R17:R17, ">1") / 4 + SUMIF(Y17:Y17, ">=70") / 4 + SUMIF(Z17:Z17, ">1") / 4 + SUMIF(AG17:AG17, ">=70") / 4 + SUMIF(AH17:AH17, ">1") / 4 -> 0 | BH17: =SUMIF(K17:K17, ">=70") / 4 +SUMIF(L17:L17, ">1") / 4 +SUMIF(S17:S17, ">=70") / 4 +SUMIF(T17:T17, ">1") / 4 + SUMIF(AA17:AA17, ">=70") / 4 + SUMIF(AB17:AB17, ">1") / 4 + SUMIF(AI17:AI17, ">=70") / 4 + SUMIF(AJ17:AJ17, ">1") / 4 -> 0 | BI17: =AVERAGE(BE17:BH17) -> 0
A18: 8 | B18: 4A-D-08 | C18: DARLENIS | D18: DE JESUS | AK18: =SUMIF(E18:E18, ">=70") / 4 +SUMIF(G18:G18, ">=70") / 4 +SUMIF(I18:I18, ">=70") / 4 +SUMIF(K18:K18, ">=70") / 4 + SUMIF(F18:F18, ">1") / 4 + SUMIF(H18:H18, ">1") / 4 + SUMIF(J18:J18, ">1") / 4 + SUMIF(L18:L18, ">1") / 4 -> 0 | AL18: =SUMIF(M18:M18, ">=70") / 4 +SUMIF(O18:O18, ">=70") / 4 +SUMIF(Q18:Q18, ">=70") / 4 +SUMIF(S18:S18, ">=70") / 4 + SUMIF(N18:N18, ">1") / 4 + SUMIF(P18:P18, ">1") / 4 + SUMIF(R18:R18, ">1") / 4 + SUMIF(T18:T18, ">1") / 4 -> 0 | AM18: =SUMIF(U18:U18, ">=70") / 4 +SUMIF(W18:W18, ">=70") / 4 +SUMIF(Y18:Y18, ">=70") / 4 +SUMIF(AA18:AA18, ">=70") / 4 + SUMIF(V18:V18, ">1") / 4 + SUMIF(X18:X18, ">1") / 4 + SUMIF(Z18:Z18, ">1") / 4 + SUMIF(AB18:AB18, ">1") / 4 -> 0 | AN18: =SUMIF(AC18:AC18, ">=65") / 4 +SUMIF(AE18:AE18, ">=65") / 4 +SUMIF(AG18:AG18, ">=65") / 4 +SUMIF(AI18:AI18, ">=65") / 4 + SUMIF(AD18:AD18, ">1") / 4 + SUMIF(AF18:AF18, ">1") / 4 + SUMIF(AH18:AH18, ">1") / 4 + SUMIF(AJ18:AJ18, ">1") / 4 -> 0 | AO18: =AVERAGE(AK18:AN18) -> 0 | AR18: =IF(AO18<70, AO18*0.5, "") -> 0 | AT18: =AS18*50% -> 0 | AU18: =IF(AS18<>"", IF(AR18="","",AR18+AT18), "") | AV18: =IF(AU18 < 70, AR18*30%, "") | AX18: =AW18*70% -> 0 | AY18: =IF(AW18<>"", IF(AV18="", "", AV18+AX18), "") | AZ18: =IF(AND(AU18<70, AY18<70), AO18, "") | BB18: =IF(AW18<>"", IF(AY18>=70, AY18, IF(AZ18+BA18>=70, AZ18+BA18, "")), IF(AS18<>"", IF(AU18>=70, AU18, ""), IF(AO18>=70, AO18, ""))) | BC18: =IF(AW18<>"", IF(AY18<70, IF(AZ18+BA18<70, AZ18+BA18, ""), ""), IF(AS18<>"", IF(AU18<70, AU18, ""), IF(AO18<70, AO18, ""))) -> 0 | BE18: =SUMIF(E18:E18, ">=70") / 4 +SUMIF(F18:F18, ">1") / 4 +SUMIF(M18:M18, ">=70") / 4 +SUMIF(N18:N18, ">1") / 4 + SUMIF(U18:U18, ">=70") / 4 + SUMIF(V18:V18, ">1") / 4 + SUMIF(AC18:AC18, ">=70") / 4 + SUMIF(AD18:AD18, ">1") / 4 -> 0 | BF18: =SUMIF(G18:G18, ">=70") / 4 +SUMIF(H18:H18, ">1") / 4 +SUMIF(O18:O18, ">=70") / 4 +SUMIF(P18:P18, ">1") / 4 + SUMIF(W18:W18, ">=70") / 4 + SUMIF(X18:X18, ">1") / 4 + SUMIF(AE18:AE18, ">=70") / 4 + SUMIF(AF18:AF18, ">1") / 4 -> 0 | BG18: =SUMIF(I18:I18, ">=70") / 4 +SUMIF(J18:J18, ">1") / 4 +SUMIF(Q18:Q18, ">=70") / 4 +SUMIF(R18:R18, ">1") / 4 + SUMIF(Y18:Y18, ">=70") / 4 + SUMIF(Z18:Z18, ">1") / 4 + SUMIF(AG18:AG18, ">=70") / 4 + SUMIF(AH18:AH18, ">1") / 4 -> 0 | BH18: =SUMIF(K18:K18, ">=70") / 4 +SUMIF(L18:L18, ">1") / 4 +SUMIF(S18:S18, ">=70") / 4 +SUMIF(T18:T18, ">1") / 4 + SUMIF(AA18:AA18, ">=70") / 4 + SUMIF(AB18:AB18, ">1") / 4 + SUMIF(AI18:AI18, ">=70") / 4 + SUMIF(AJ18:AJ18, ">1") / 4 -> 0 | BI18: =AVERAGE(BE18:BH18) -> 0
A19: 9 | B19: 4A-D-09 | C19: DUBAN | D19: ZABALA | AK19: =SUMIF(E19:E19, ">=70") / 4 +SUMIF(G19:G19, ">=70") / 4 +SUMIF(I19:I19, ">=70") / 4 +SUMIF(K19:K19, ">=70") / 4 + SUMIF(F19:F19, ">1") / 4 + SUMIF(H19:H19, ">1") / 4 + SUMIF(J19:J19, ">1") / 4 + SUMIF(L19:L19, ">1") / 4 -> 0 | AL19: =SUMIF(M19:M19, ">=70") / 4 +SUMIF(O19:O19, ">=70") / 4 +SUMIF(Q19:Q19, ">=70") / 4 +SUMIF(S19:S19, ">=70") / 4 + SUMIF(N19:N19, ">1") / 4 + SUMIF(P19:P19, ">1") / 4 + SUMIF(R19:R19, ">1") / 4 + SUMIF(T19:T19, ">1") / 4 -> 0 | AM19: =SUMIF(U19:U19, ">=70") / 4 +SUMIF(W19:W19, ">=70") / 4 +SUMIF(Y19:Y19, ">=70") / 4 +SUMIF(AA19:AA19, ">=70") / 4 + SUMIF(V19:V19, ">1") / 4 + SUMIF(X19:X19, ">1") / 4 + SUMIF(Z19:Z19, ">1") / 4 + SUMIF(AB19:AB19, ">1") / 4 -> 0 | AN19: =SUMIF(AC19:AC19, ">=65") / 4 +SUMIF(AE19:AE19, ">=65") / 4 +SUMIF(AG19:AG19, ">=65") / 4 +SUMIF(AI19:AI19, ">=65") / 4 + SUMIF(AD19:AD19, ">1") / 4 + SUMIF(AF19:AF19, ">1") / 4 + SUMIF(AH19:AH19, ">1") / 4 + SUMIF(AJ19:AJ19, ">1") / 4 -> 0 | AO19: =AVERAGE(AK19:AN19) -> 0 | AR19: =IF(AO19<70, AO19*0.5, "") -> 0 | AT19: =AS19*50% -> 0 | AU19: =IF(AS19<>"", IF(AR19="","",AR19+AT19), "") | AV19: =IF(AU19 < 70, AR19*30%, "") | AX19: =AW19*70% -> 0 | AY19: =IF(AW19<>"", IF(AV19="", "", AV19+AX19), "") | AZ19: =IF(AND(AU19<70, AY19<70), AO19, "") | BB19: =IF(AW19<>"", IF(AY19>=70, AY19, IF(AZ19+BA19>=70, AZ19+BA19, "")), IF(AS19<>"", IF(AU19>=70, AU19, ""), IF(AO19>=70, AO19, ""))) | BC19: =IF(AW19<>"", IF(AY19<70, IF(AZ19+BA19<70, AZ19+BA19, ""), ""), IF(AS19<>"", IF(AU19<70, AU19, ""), IF(AO19<70, AO19, ""))) -> 0 | BE19: =SUMIF(E19:E19, ">=70") / 4 +SUMIF(F19:F19, ">1") / 4 +SUMIF(M19:M19, ">=70") / 4 +SUMIF(N19:N19, ">1") / 4 + SUMIF(U19:U19, ">=70") / 4 + SUMIF(V19:V19, ">1") / 4 + SUMIF(AC19:AC19, ">=70") / 4 + SUMIF(AD19:AD19, ">1") / 4 -> 0 | BF19: =SUMIF(G19:G19, ">=70") / 4 +SUMIF(H19:H19, ">1") / 4 +SUMIF(O19:O19, ">=70") / 4 +SUMIF(P19:P19, ">1") / 4 + SUMIF(W19:W19, ">=70") / 4 + SUMIF(X19:X19, ">1") / 4 + SUMIF(AE19:AE19, ">=70") / 4 + SUMIF(AF19:AF19, ">1") / 4 -> 0 | BG19: =SUMIF(I19:I19, ">=70") / 4 +SUMIF(J19:J19, ">1") / 4 +SUMIF(Q19:Q19, ">=70") / 4 +SUMIF(R19:R19, ">1") / 4 + SUMIF(Y19:Y19, ">=70") / 4 + SUMIF(Z19:Z19, ">1") / 4 + SUMIF(AG19:AG19, ">=70") / 4 + SUMIF(AH19:AH19, ">1") / 4 -> 0 | BH19: =SUMIF(K19:K19, ">=70") / 4 +SUMIF(L19:L19, ">1") / 4 +SUMIF(S19:S19, ">=70") / 4 +SUMIF(T19:T19, ">1") / 4 + SUMIF(AA19:AA19, ">=70") / 4 + SUMIF(AB19:AB19, ">1") / 4 + SUMIF(AI19:AI19, ">=70") / 4 + SUMIF(AJ19:AJ19, ">1") / 4 -> 0 | BI19: =AVERAGE(BE19:BH19) -> 0
A20: 10 | B20: 4A-D-10 | C20: EDILEYNI | D20: DE LOS SANTOS | AK20: =SUMIF(E20:E20, ">=70") / 4 +SUMIF(G20:G20, ">=70") / 4 +SUMIF(I20:I20, ">=70") / 4 +SUMIF(K20:K20, ">=70") / 4 + SUMIF(F20:F20, ">1") / 4 + SUMIF(H20:H20, ">1") / 4 + SUMIF(J20:J20, ">1") / 4 + SUMIF(L20:L20, ">1") / 4 -> 0 | AL20: =SUMIF(M20:M20, ">=70") / 4 +SUMIF(O20:O20, ">=70") / 4 +SUMIF(Q20:Q20, ">=70") / 4 +SUMIF(S20:S20, ">=70") / 4 + SUMIF(N20:N20, ">1") / 4 + SUMIF(P20:P20, ">1") / 4 + SUMIF(R20:R20, ">1") / 4 + SUMIF(T20:T20, ">1") / 4 -> 0 | AM20: =SUMIF(U20:U20, ">=70") / 4 +SUMIF(W20:W20, ">=70") / 4 +SUMIF(Y20:Y20, ">=70") / 4 +SUMIF(AA20:AA20, ">=70") / 4 + SUMIF(V20:V20, ">1") / 4 + SUMIF(X20:X20, ">1") / 4 + SUMIF(Z20:Z20, ">1") / 4 + SUMIF(AB20:AB20, ">1") / 4 -> 0 | AN20: =SUMIF(AC20:AC20, ">=65") / 4 +SUMIF(AE20:AE20, ">=65") / 4 +SUMIF(AG20:AG20, ">=65") / 4 +SUMIF(AI20:AI20, ">=65") / 4 + SUMIF(AD20:AD20, ">1") / 4 + SUMIF(AF20:AF20, ">1") / 4 + SUMIF(AH20:AH20, ">1") / 4 + SUMIF(AJ20:AJ20, ">1") / 4 -> 0 | AO20: =AVERAGE(AK20:AN20) -> 0 | AR20: =IF(AO20<70, AO20*0.5, "") -> 0 | AT20: =AS20*50% -> 0 | AU20: =IF(AS20<>"", IF(AR20="","",AR20+AT20), "") | AV20: =IF(AU20 < 70, AR20*30%, "") | AX20: =AW20*70% -> 0 | AY20: =IF(AW20<>"", IF(AV20="", "", AV20+AX20), "") | AZ20: =IF(AND(AU20<70, AY20<70), AO20, "") | BB20: =IF(AW20<>"", IF(AY20>=70, AY20, IF(AZ20+BA20>=70, AZ20+BA20, "")), IF(AS20<>"", IF(AU20>=70, AU20, ""), IF(AO20>=70, AO20, ""))) | BC20: =IF(AW20<>"", IF(AY20<70, IF(AZ20+BA20<70, AZ20+BA20, ""), ""), IF(AS20<>"", IF(AU20<70, AU20, ""), IF(AO20<70, AO20, ""))) -> 0 | BE20: =SUMIF(E20:E20, ">=70") / 4 +SUMIF(F20:F20, ">1") / 4 +SUMIF(M20:M20, ">=70") / 4 +SUMIF(N20:N20, ">1") / 4 + SUMIF(U20:U20, ">=70") / 4 + SUMIF(V20:V20, ">1") / 4 + SUMIF(AC20:AC20, ">=70") / 4 + SUMIF(AD20:AD20, ">1") / 4 -> 0 | BF20: =SUMIF(G20:G20, ">=70") / 4 +SUMIF(H20:H20, ">1") / 4 +SUMIF(O20:O20, ">=70") / 4 +SUMIF(P20:P20, ">1") / 4 + SUMIF(W20:W20, ">=70") / 4 + SUMIF(X20:X20, ">1") / 4 + SUMIF(AE20:AE20, ">=70") / 4 + SUMIF(AF20:AF20, ">1") / 4 -> 0 | BG20: =SUMIF(I20:I20, ">=70") / 4 +SUMIF(J20:J20, ">1") / 4 +SUMIF(Q20:Q20, ">=70") / 4 +SUMIF(R20:R20, ">1") / 4 + SUMIF(Y20:Y20, ">=70") / 4 + SUMIF(Z20:Z20, ">1") / 4 + SUMIF(AG20:AG20, ">=70") / 4 + SUMIF(AH20:AH20, ">1") / 4 -> 0 | BH20: =SUMIF(K20:K20, ">=70") / 4 +SUMIF(L20:L20, ">1") / 4 +SUMIF(S20:S20, ">=70") / 4 +SUMIF(T20:T20, ">1") / 4 + SUMIF(AA20:AA20, ">=70") / 4 + SUMIF(AB20:AB20, ">1") / 4 + SUMIF(AI20:AI20, ">=70") / 4 + SUMIF(AJ20:AJ20, ">1") / 4 -> 0 | BI20: =AVERAGE(BE20:BH20) -> 0
A21: 11 | B21: 4A-D-11 | C21: ENYEL | D21: MANZANILLO JAVIER | AK21: =SUMIF(E21:E21, ">=70") / 4 +SUMIF(G21:G21, ">=70") / 4 +SUMIF(I21:I21, ">=70") / 4 +SUMIF(K21:K21, ">=70") / 4 + SUMIF(F21:F21, ">1") / 4 + SUMIF(H21:H21, ">1") / 4 + SUMIF(J21:J21, ">1") / 4 + SUMIF(L21:L21, ">1") / 4 -> 0 | AL21: =SUMIF(M21:M21, ">=70") / 4 +SUMIF(O21:O21, ">=70") / 4 +SUMIF(Q21:Q21, ">=70") / 4 +SUMIF(S21:S21, ">=70") / 4 + SUMIF(N21:N21, ">1") / 4 + SUMIF(P21:P21, ">1") / 4 + SUMIF(R21:R21, ">1") / 4 + SUMIF(T21:T21, ">1") / 4 -> 0 | AM21: =SUMIF(U21:U21, ">=70") / 4 +SUMIF(W21:W21, ">=70") / 4 +SUMIF(Y21:Y21, ">=70") / 4 +SUMIF(AA21:AA21, ">=70") / 4 + SUMIF(V21:V21, ">1") / 4 + SUMIF(X21:X21, ">1") / 4 + SUMIF(Z21:Z21, ">1") / 4 + SUMIF(AB21:AB21, ">1") / 4 -> 0 | AN21: =SUMIF(AC21:AC21, ">=65") / 4 +SUMIF(AE21:AE21, ">=65") / 4 +SUMIF(AG21:AG21, ">=65") / 4 +SUMIF(AI21:AI21, ">=65") / 4 + SUMIF(AD21:AD21, ">1") / 4 + SUMIF(AF21:AF21, ">1") / 4 + SUMIF(AH21:AH21, ">1") / 4 + SUMIF(AJ21:AJ21, ">1") / 4 -> 0 | AO21: =AVERAGE(AK21:AN21) -> 0 | AR21: =IF(AO21<70, AO21*0.5, "") -> 0 | AT21: =AS21*50% -> 0 | AU21: =IF(AS21<>"", IF(AR21="","",AR21+AT21), "") | AV21: =IF(AU21 < 70, AR21*30%, "") | AX21: =AW21*70% -> 0 | AY21: =IF(AW21<>"", IF(AV21="", "", AV21+AX21), "") | AZ21: =IF(AND(AU21<70, AY21<70), AO21, "") | BB21: =IF(AW21<>"", IF(AY21>=70, AY21, IF(AZ21+BA21>=70, AZ21+BA21, "")), IF(AS21<>"", IF(AU21>=70, AU21, ""), IF(AO21>=70, AO21, ""))) | BC21: =IF(AW21<>"", IF(AY21<70, IF(AZ21+BA21<70, AZ21+BA21, ""), ""), IF(AS21<>"", IF(AU21<70, AU21, ""), IF(AO21<70, AO21, ""))) -> 0 | BE21: =SUMIF(E21:E21, ">=70") / 4 +SUMIF(F21:F21, ">1") / 4 +SUMIF(M21:M21, ">=70") / 4 +SUMIF(N21:N21, ">1") / 4 + SUMIF(U21:U21, ">=70") / 4 + SUMIF(V21:V21, ">1") / 4 + SUMIF(AC21:AC21, ">=70") / 4 + SUMIF(AD21:AD21, ">1") / 4 -> 0 | BF21: =SUMIF(G21:G21, ">=70") / 4 +SUMIF(H21:H21, ">1") / 4 +SUMIF(O21:O21, ">=70") / 4 +SUMIF(P21:P21, ">1") / 4 + SUMIF(W21:W21, ">=70") / 4 + SUMIF(X21:X21, ">1") / 4 + SUMIF(AE21:AE21, ">=70") / 4 + SUMIF(AF21:AF21, ">1") / 4 -> 0 | BG21: =SUMIF(I21:I21, ">=70") / 4 +SUMIF(J21:J21, ">1") / 4 +SUMIF(Q21:Q21, ">=70") / 4 +SUMIF(R21:R21, ">1") / 4 + SUMIF(Y21:Y21, ">=70") / 4 + SUMIF(Z21:Z21, ">1") / 4 + SUMIF(AG21:AG21, ">=70") / 4 + SUMIF(AH21:AH21, ">1") / 4 -> 0 | BH21: =SUMIF(K21:K21, ">=70") / 4 +SUMIF(L21:L21, ">1") / 4 +SUMIF(S21:S21, ">=70") / 4 +SUMIF(T21:T21, ">1") / 4 + SUMIF(AA21:AA21, ">=70") / 4 + SUMIF(AB21:AB21, ">1") / 4 + SUMIF(AI21:AI21, ">=70") / 4 + SUMIF(AJ21:AJ21, ">1") / 4 -> 0 | BI21: =AVERAGE(BE21:BH21) -> 0
A22: 12 | B22: 4A-D-12 | C22: ESNAIDER | D22: ALMANZAR SEVERINO | AK22: =SUMIF(E22:E22, ">=70") / 4 +SUMIF(G22:G22, ">=70") / 4 +SUMIF(I22:I22, ">=70") / 4 +SUMIF(K22:K22, ">=70") / 4 + SUMIF(F22:F22, ">1") / 4 + SUMIF(H22:H22, ">1") / 4 + SUMIF(J22:J22, ">1") / 4 + SUMIF(L22:L22, ">1") / 4 -> 0 | AL22: =SUMIF(M22:M22, ">=70") / 4 +SUMIF(O22:O22, ">=70") / 4 +SUMIF(Q22:Q22, ">=70") / 4 +SUMIF(S22:S22, ">=70") / 4 + SUMIF(N22:N22, ">1") / 4 + SUMIF(P22:P22, ">1") / 4 + SUMIF(R22:R22, ">1") / 4 + SUMIF(T22:T22, ">1") / 4 -> 0 | AM22: =SUMIF(U22:U22, ">=70") / 4 +SUMIF(W22:W22, ">=70") / 4 +SUMIF(Y22:Y22, ">=70") / 4 +SUMIF(AA22:AA22, ">=70") / 4 + SUMIF(V22:V22, ">1") / 4 + SUMIF(X22:X22, ">1") / 4 + SUMIF(Z22:Z22, ">1") / 4 + SUMIF(AB22:AB22, ">1") / 4 -> 0 | AN22: =SUMIF(AC22:AC22, ">=65") / 4 +SUMIF(AE22:AE22, ">=65") / 4 +SUMIF(AG22:AG22, ">=65") / 4 +SUMIF(AI22:AI22, ">=65") / 4 + SUMIF(AD22:AD22, ">1") / 4 + SUMIF(AF22:AF22, ">1") / 4 + SUMIF(AH22:AH22, ">1") / 4 + SUMIF(AJ22:AJ22, ">1") / 4 -> 0 | AO22: =AVERAGE(AK22:AN22) -> 0 | AR22: =IF(AO22<70, AO22*0.5, "") -> 0 | AT22: =AS22*50% -> 0 | AU22: =IF(AS22<>"", IF(AR22="","",AR22+AT22), "") | AV22: =IF(AU22 < 70, AR22*30%, "") | AX22: =AW22*70% -> 0 | AY22: =IF(AW22<>"", IF(AV22="", "", AV22+AX22), "") | AZ22: =IF(AND(AU22<70, AY22<70), AO22, "") | BB22: =IF(AW22<>"", IF(AY22>=70, AY22, IF(AZ22+BA22>=70, AZ22+BA22, "")), IF(AS22<>"", IF(AU22>=70, AU22, ""), IF(AO22>=70, AO22, ""))) | BC22: =IF(AW22<>"", IF(AY22<70, IF(AZ22+BA22<70, AZ22+BA22, ""), ""), IF(AS22<>"", IF(AU22<70, AU22, ""), IF(AO22<70, AO22, ""))) -> 0 | BE22: =SUMIF(E22:E22, ">=70") / 4 +SUMIF(F22:F22, ">1") / 4 +SUMIF(M22:M22, ">=70") / 4 +SUMIF(N22:N22, ">1") / 4 + SUMIF(U22:U22, ">=70") / 4 + SUMIF(V22:V22, ">1") / 4 + SUMIF(AC22:AC22, ">=70") / 4 + SUMIF(AD22:AD22, ">1") / 4 -> 0 | BF22: =SUMIF(G22:G22, ">=70") / 4 +SUMIF(H22:H22, ">1") / 4 +SUMIF(O22:O22, ">=70") / 4 +SUMIF(P22:P22, ">1") / 4 + SUMIF(W22:W22, ">=70") / 4 + SUMIF(X22:X22, ">1") / 4 + SUMIF(AE22:AE22, ">=70") / 4 + SUMIF(AF22:AF22, ">1") / 4 -> 0 | BG22: =SUMIF(I22:I22, ">=70") / 4 +SUMIF(J22:J22, ">1") / 4 +SUMIF(Q22:Q22, ">=70") / 4 +SUMIF(R22:R22, ">1") / 4 + SUMIF(Y22:Y22, ">=70") / 4 + SUMIF(Z22:Z22, ">1") / 4 + SUMIF(AG22:AG22, ">=70") / 4 + SUMIF(AH22:AH22, ">1") / 4 -> 0 | BH22: =SUMIF(K22:K22, ">=70") / 4 +SUMIF(L22:L22, ">1") / 4 +SUMIF(S22:S22, ">=70") / 4 +SUMIF(T22:T22, ">1") / 4 + SUMIF(AA22:AA22, ">=70") / 4 + SUMIF(AB22:AB22, ">1") / 4 + SUMIF(AI22:AI22, ">=70") / 4 + SUMIF(AJ22:AJ22, ">1") / 4 -> 0 | BI22: =AVERAGE(BE22:BH22) -> 0
A23: 13 | B23: 4A-D-13 | C23: EVA MARIA | D23: DIAZ | AK23: =SUMIF(E23:E23, ">=70") / 4 +SUMIF(G23:G23, ">=70") / 4 +SUMIF(I23:I23, ">=70") / 4 +SUMIF(K23:K23, ">=70") / 4 + SUMIF(F23:F23, ">1") / 4 + SUMIF(H23:H23, ">1") / 4 + SUMIF(J23:J23, ">1") / 4 + SUMIF(L23:L23, ">1") / 4 -> 0 | AL23: =SUMIF(M23:M23, ">=70") / 4 +SUMIF(O23:O23, ">=70") / 4 +SUMIF(Q23:Q23, ">=70") / 4 +SUMIF(S23:S23, ">=70") / 4 + SUMIF(N23:N23, ">1") / 4 + SUMIF(P23:P23, ">1") / 4 + SUMIF(R23:R23, ">1") / 4 + SUMIF(T23:T23, ">1") / 4 -> 0 | AM23: =SUMIF(U23:U23, ">=70") / 4 +SUMIF(W23:W23, ">=70") / 4 +SUMIF(Y23:Y23, ">=70") / 4 +SUMIF(AA23:AA23, ">=70") / 4 + SUMIF(V23:V23, ">1") / 4 + SUMIF(X23:X23, ">1") / 4 + SUMIF(Z23:Z23, ">1") / 4 + SUMIF(AB23:AB23, ">1") / 4 -> 0 | AN23: =SUMIF(AC23:AC23, ">=65") / 4 +SUMIF(AE23:AE23, ">=65") / 4 +SUMIF(AG23:AG23, ">=65") / 4 +SUMIF(AI23:AI23, ">=65") / 4 + SUMIF(AD23:AD23, ">1") / 4 + SUMIF(AF23:AF23, ">1") / 4 + SUMIF(AH23:AH23, ">1") / 4 + SUMIF(AJ23:AJ23, ">1") / 4 -> 0 | AO23: =AVERAGE(AK23:AN23) -> 0 | AR23: =IF(AO23<70, AO23*0.5, "") -> 0 | AT23: =AS23*50% -> 0 | AU23: =IF(AS23<>"", IF(AR23="","",AR23+AT23), "") | AV23: =IF(AU23 < 70, AR23*30%, "") | AX23: =AW23*70% -> 0 | AY23: =IF(AW23<>"", IF(AV23="", "", AV23+AX23), "") | AZ23: =IF(AND(AU23<70, AY23<70), AO23, "") | BB23: =IF(AW23<>"", IF(AY23>=70, AY23, IF(AZ23+BA23>=70, AZ23+BA23, "")), IF(AS23<>"", IF(AU23>=70, AU23, ""), IF(AO23>=70, AO23, ""))) | BC23: =IF(AW23<>"", IF(AY23<70, IF(AZ23+BA23<70, AZ23+BA23, ""), ""), IF(AS23<>"", IF(AU23<70, AU23, ""), IF(AO23<70, AO23, ""))) -> 0 | BE23: =SUMIF(E23:E23, ">=70") / 4 +SUMIF(F23:F23, ">1") / 4 +SUMIF(M23:M23, ">=70") / 4 +SUMIF(N23:N23, ">1") / 4 + SUMIF(U23:U23, ">=70") / 4 + SUMIF(V23:V23, ">1") / 4 + SUMIF(AC23:AC23, ">=70") / 4 + SUMIF(AD23:AD23, ">1") / 4 -> 0 | BF23: =SUMIF(G23:G23, ">=70") / 4 +SUMIF(H23:H23, ">1") / 4 +SUMIF(O23:O23, ">=70") / 4 +SUMIF(P23:P23, ">1") / 4 + SUMIF(W23:W23, ">=70") / 4 + SUMIF(X23:X23, ">1") / 4 + SUMIF(AE23:AE23, ">=70") / 4 + SUMIF(AF23:AF23, ">1") / 4 -> 0 | BG23: =SUMIF(I23:I23, ">=70") / 4 +SUMIF(J23:J23, ">1") / 4 +SUMIF(Q23:Q23, ">=70") / 4 +SUMIF(R23:R23, ">1") / 4 + SUMIF(Y23:Y23, ">=70") / 4 + SUMIF(Z23:Z23, ">1") / 4 + SUMIF(AG23:AG23, ">=70") / 4 + SUMIF(AH23:AH23, ">1") / 4 -> 0 | BH23: =SUMIF(K23:K23, ">=70") / 4 +SUMIF(L23:L23, ">1") / 4 +SUMIF(S23:S23, ">=70") / 4 +SUMIF(T23:T23, ">1") / 4 + SUMIF(AA23:AA23, ">=70") / 4 + SUMIF(AB23:AB23, ">1") / 4 + SUMIF(AI23:AI23, ">=70") / 4 + SUMIF(AJ23:AJ23, ">1") / 4 -> 0 | BI23: =AVERAGE(BE23:BH23) -> 0
... A40: 30 | B40: 4A-D-30 | C40: YOLI MARIA | D40: RODRIGUEZ CASTRO | AK40: =SUMIF(E40:E40, ">=70") / 4 +SUMIF(G40:G40, ">=70") / 4 +SUMIF(I40:I40, ">=70") / 4 +SUMIF(K40:K40, ">=70") / 4 + SUMIF(F40:F40, ">1") / 4 + SUMIF(H40:H40, ">1") / 4 + SUMIF(J40:J40, ">1") / 4 + SUMIF(L40:L40, ">1") / 4 -> 0 | AL40: =SUMIF(M40:M40, ">=70") / 4 +SUMIF(O40:O40, ">=70") / 4 +SUMIF(Q40:Q40, ">=70") / 4 +SUMIF(S40:S40, ">=70") / 4 + SUMIF(N40:N40, ">1") / 4 + SUMIF(P40:P40, ">1") / 4 + SUMIF(R40:R40, ">1") / 4 + SUMIF(T40:T40, ">1") / 4 -> 0 | AM40: =SUMIF(U40:U40, ">=70") / 4 +SUMIF(W40:W40, ">=70") / 4 +SUMIF(Y40:Y40, ">=70") / 4 +SUMIF(AA40:AA40, ">=70") / 4 + SUMIF(V40:V40, ">1") / 4 + SUMIF(X40:X40, ">1") / 4 + SUMIF(Z40:Z40, ">1") / 4 + SUMIF(AB40:AB40, ">1") / 4 -> 0 | AN40: =SUMIF(AC40:AC40, ">=65") / 4 +SUMIF(AE40:AE40, ">=65") / 4 +SUMIF(AG40:AG40, ">=65") / 4 +SUMIF(AI40:AI40, ">=65") / 4 + SUMIF(AD40:AD40, ">1") / 4 + SUMIF(AF40:AF40, ">1") / 4 + SUMIF(AH40:AH40, ">1") / 4 + SUMIF(AJ40:AJ40, ">1") / 4 -> 0 | AO40: =AVERAGE(AK40:AN40) -> 0 | AR40: =IF(AO40<70, AO40*0.5, "") -> 0 | AT40: =AS40*50% -> 0 | AU40: =IF(AS40<>"", IF(AR40="","",AR40+AT40), "") | AV40: =IF(AU40 < 70, AR40*30%, "") | AX40: =AW40*70% -> 0 | AY40: =IF(AW40<>"", IF(AV40="", "", AV40+AX40), "") | AZ40: =IF(AND(AU40<70, AY40<70), AO40, "") | BB40: =IF(AW40<>"", IF(AY40>=70, AY40, IF(AZ40+BA40>=70, AZ40+BA40, "")), IF(AS40<>"", IF(AU40>=70, AU40, ""), IF(AO40>=70, AO40, ""))) | BC40: =IF(AW40<>"", IF(AY40<70, IF(AZ40+BA40<70, AZ40+BA40, ""), ""), IF(AS40<>"", IF(AU40<70, AU40, ""), IF(AO40<70, AO40, ""))) -> 0 | BE40: =SUMIF(E40:E40, ">=70") / 4 +SUMIF(F40:F40, ">1") / 4 +SUMIF(M40:M40, ">=70") / 4 +SUMIF(N40:N40, ">1") / 4 + SUMIF(U40:U40, ">=70") / 4 + SUMIF(V40:V40, ">1") / 4 + SUMIF(AC40:AC40, ">=70") / 4 + SUMIF(AD40:AD40, ">1") / 4 -> 0 | BF40: =SUMIF(G40:G40, ">=70") / 4 +SUMIF(H40:H40, ">1") / 4 +SUMIF(O40:O40, ">=70") / 4 +SUMIF(P40:P40, ">1") / 4 + SUMIF(W40:W40, ">=70") / 4 + SUMIF(X40:X40, ">1") / 4 + SUMIF(AE40:AE40, ">=70") / 4 + SUMIF(AF40:AF40, ">1") / 4 -> 0 | BG40: =SUMIF(I40:I40, ">=70") / 4 +SUMIF(J40:J40, ">1") / 4 +SUMIF(Q40:Q40, ">=70") / 4 +SUMIF(R40:R40, ">1") / 4 + SUMIF(Y40:Y40, ">=70") / 4 + SUMIF(Z40:Z40, ">1") / 4 + SUMIF(AG40:AG40, ">=70") / 4 + SUMIF(AH40:AH40, ">1") / 4 -> 0 | BH40: =SUMIF(K40:K40, ">=70") / 4 +SUMIF(L40:L40, ">1") / 4 +SUMIF(S40:S40, ">=70") / 4 +SUMIF(T40:T40, ">1") / 4 + SUMIF(AA40:AA40, ">=70") / 4 + SUMIF(AB40:AB40, ">1") / 4 + SUMIF(AI40:AI40, ">=70") / 4 + SUMIF(AJ40:AJ40, ">1") / 4 -> 0 | BI40: =AVERAGE(BE40:BH40) -> 0
A41: 31 | B41: 4A-D-31 | AK41: =SUMIF(E41:E41, ">=70") / 4 +SUMIF(G41:G41, ">=70") / 4 +SUMIF(I41:I41, ">=70") / 4 +SUMIF(K41:K41, ">=70") / 4 + SUMIF(F41:F41, ">1") / 4 + SUMIF(H41:H41, ">1") / 4 + SUMIF(J41:J41, ">1") / 4 + SUMIF(L41:L41, ">1") / 4 -> 0 | AL41: =SUMIF(M41:M41, ">=70") / 4 +SUMIF(O41:O41, ">=70") / 4 +SUMIF(Q41:Q41, ">=70") / 4 +SUMIF(S41:S41, ">=70") / 4 + SUMIF(N41:N41, ">1") / 4 + SUMIF(P41:P41, ">1") / 4 + SUMIF(R41:R41, ">1") / 4 + SUMIF(T41:T41, ">1") / 4 -> 0 | AM41: =SUMIF(U41:U41, ">=70") / 4 +SUMIF(W41:W41, ">=70") / 4 +SUMIF(Y41:Y41, ">=70") / 4 +SUMIF(AA41:AA41, ">=70") / 4 + SUMIF(V41:V41, ">1") / 4 + SUMIF(X41:X41, ">1") / 4 + SUMIF(Z41:Z41, ">1") / 4 + SUMIF(AB41:AB41, ">1") / 4 -> 0 | AN41: =SUMIF(AC41:AC41, ">=65") / 4 +SUMIF(AE41:AE41, ">=65") / 4 +SUMIF(AG41:AG41, ">=65") / 4 +SUMIF(AI41:AI41, ">=65") / 4 + SUMIF(AD41:AD41, ">1") / 4 + SUMIF(AF41:AF41, ">1") / 4 + SUMIF(AH41:AH41, ">1") / 4 + SUMIF(AJ41:AJ41, ">1") / 4 -> 0 | AO41: =AVERAGE(AK41:AN41) -> 0 | AR41: =IF(AO41<70, AO41*0.5, "") -> 0 | AT41: =AS41*50% -> 0 | AU41: =IF(AS41<>"", IF(AR41="","",AR41+AT41), "") | AV41: =IF(AU41 < 70, AR41*30%, "") | AX41: =AW41*70% -> 0 | AY41: =IF(AW41<>"", IF(AV41="", "", AV41+AX41), "") | AZ41: =IF(AND(AU41<70, AY41<70), AO41, "") | BB41: =IF(AW41<>"", IF(AY41>=70, AY41, IF(AZ41+BA41>=70, AZ41+BA41, "")), IF(AS41<>"", IF(AU41>=70, AU41, ""), IF(AO41>=70, AO41, ""))) | BC41: =IF(AW41<>"", IF(AY41<70, IF(AZ41+BA41<70, AZ41+BA41, ""), ""), IF(AS41<>"", IF(AU41<70, AU41, ""), IF(AO41<70, AO41, ""))) -> 0 | BE41: =SUMIF(E41:E41, ">=70") / 4 +SUMIF(F41:F41, ">1") / 4 +SUMIF(M41:M41, ">=70") / 4 +SUMIF(N41:N41, ">1") / 4 + SUMIF(U41:U41, ">=70") / 4 + SUMIF(V41:V41, ">1") / 4 + SUMIF(AC41:AC41, ">=70") / 4 + SUMIF(AD41:AD41, ">1") / 4 -> 0 | BF41: =SUMIF(G41:G41, ">=70") / 4 +SUMIF(H41:H41, ">1") / 4 +SUMIF(O41:O41, ">=70") / 4 +SUMIF(P41:P41, ">1") / 4 + SUMIF(W41:W41, ">=70") / 4 + SUMIF(X41:X41, ">1") / 4 + SUMIF(AE41:AE41, ">=70") / 4 + SUMIF(AF41:AF41, ">1") / 4 -> 0 | BG41: =SUMIF(I41:I41, ">=70") / 4 +SUMIF(J41:J41, ">1") / 4 +SUMIF(Q41:Q41, ">=70") / 4 +SUMIF(R41:R41, ">1") / 4 + SUMIF(Y41:Y41, ">=70") / 4 + SUMIF(Z41:Z41, ">1") / 4 + SUMIF(AG41:AG41, ">=70") / 4 + SUMIF(AH41:AH41, ">1") / 4 -> 0 | BH41: =SUMIF(K41:K41, ">=70") / 4 +SUMIF(L41:L41, ">1") / 4 +SUMIF(S41:S41, ">=70") / 4 +SUMIF(T41:T41, ">1") / 4 + SUMIF(AA41:AA41, ">=70") / 4 + SUMIF(AB41:AB41, ">1") / 4 + SUMIF(AI41:AI41, ">=70") / 4 + SUMIF(AJ41:AJ41, ">1") / 4 -> 0 | BI41: =AVERAGE(BE41:BH41) -> 0
A42: 32 | B42: 4A-D-32 | AK42: =SUMIF(E42:E42, ">=70") / 4 +SUMIF(G42:G42, ">=70") / 4 +SUMIF(I42:I42, ">=70") / 4 +SUMIF(K42:K42, ">=70") / 4 + SUMIF(F42:F42, ">1") / 4 + SUMIF(H42:H42, ">1") / 4 + SUMIF(J42:J42, ">1") / 4 + SUMIF(L42:L42, ">1") / 4 -> 0 | AL42: =SUMIF(M42:M42, ">=70") / 4 +SUMIF(O42:O42, ">=70") / 4 +SUMIF(Q42:Q42, ">=70") / 4 +SUMIF(S42:S42, ">=70") / 4 + SUMIF(N42:N42, ">1") / 4 + SUMIF(P42:P42, ">1") / 4 + SUMIF(R42:R42, ">1") / 4 + SUMIF(T42:T42, ">1") / 4 -> 0 | AM42: =SUMIF(U42:U42, ">=70") / 4 +SUMIF(W42:W42, ">=70") / 4 +SUMIF(Y42:Y42, ">=70") / 4 +SUMIF(AA42:AA42, ">=70") / 4 + SUMIF(V42:V42, ">1") / 4 + SUMIF(X42:X42, ">1") / 4 + SUMIF(Z42:Z42, ">1") / 4 + SUMIF(AB42:AB42, ">1") / 4 -> 0 | AN42: =SUMIF(AC42:AC42, ">=65") / 4 +SUMIF(AE42:AE42, ">=65") / 4 +SUMIF(AG42:AG42, ">=65") / 4 +SUMIF(AI42:AI42, ">=65") / 4 + SUMIF(AD42:AD42, ">1") / 4 + SUMIF(AF42:AF42, ">1") / 4 + SUMIF(AH42:AH42, ">1") / 4 + SUMIF(AJ42:AJ42, ">1") / 4 -> 0 | AO42: =AVERAGE(AK42:AN42) -> 0 | AR42: =IF(AO42<70, AO42*0.5, "") -> 0 | AT42: =AS42*50% -> 0 | AU42: =IF(AS42<>"", IF(AR42="","",AR42+AT42), "") | AV42: =IF(AU42 < 70, AR42*30%, "") | AX42: =AW42*70% -> 0 | AY42: =IF(AW42<>"", IF(AV42="", "", AV42+AX42), "") | AZ42: =IF(AND(AU42<70, AY42<70), AO42, "") | BB42: =IF(AW42<>"", IF(AY42>=70, AY42, IF(AZ42+BA42>=70, AZ42+BA42, "")), IF(AS42<>"", IF(AU42>=70, AU42, ""), IF(AO42>=70, AO42, ""))) | BC42: =IF(AW42<>"", IF(AY42<70, IF(AZ42+BA42<70, AZ42+BA42, ""), ""), IF(AS42<>"", IF(AU42<70, AU42, ""), IF(AO42<70, AO42, ""))) -> 0 | BE42: =SUMIF(E42:E42, ">=70") / 4 +SUMIF(F42:F42, ">1") / 4 +SUMIF(M42:M42, ">=70") / 4 +SUMIF(N42:N42, ">1") / 4 + SUMIF(U42:U42, ">=70") / 4 + SUMIF(V42:V42, ">1") / 4 + SUMIF(AC42:AC42, ">=70") / 4 + SUMIF(AD42:AD42, ">1") / 4 -> 0 | BF42: =SUMIF(G42:G42, ">=70") / 4 +SUMIF(H42:H42, ">1") / 4 +SUMIF(O42:O42, ">=70") / 4 +SUMIF(P42:P42, ">1") / 4 + SUMIF(W42:W42, ">=70") / 4 + SUMIF(X42:X42, ">1") / 4 + SUMIF(AE42:AE42, ">=70") / 4 + SUMIF(AF42:AF42, ">1") / 4 -> 0 | BG42: =SUMIF(I42:I42, ">=70") / 4 +SUMIF(J42:J42, ">1") / 4 +SUMIF(Q42:Q42, ">=70") / 4 +SUMIF(R42:R42, ">1") / 4 + SUMIF(Y42:Y42, ">=70") / 4 + SUMIF(Z42:Z42, ">1") / 4 + SUMIF(AG42:AG42, ">=70") / 4 + SUMIF(AH42:AH42, ">1") / 4 -> 0 | BH42: =SUMIF(K42:K42, ">=70") / 4 +SUMIF(L42:L42, ">1") / 4 +SUMIF(S42:S42, ">=70") / 4 +SUMIF(T42:T42, ">1") / 4 + SUMIF(AA42:AA42, ">=70") / 4 + SUMIF(AB42:AB42, ">1") / 4 + SUMIF(AI42:AI42, ">=70") / 4 + SUMIF(AJ42:AJ42, ">1") / 4 -> 0 | BI42: =AVERAGE(BE42:BH42) -> 0
A43: 33 | B43: 4A-D-33 | AK43: =SUMIF(E43:E43, ">=70") / 4 +SUMIF(G43:G43, ">=70") / 4 +SUMIF(I43:I43, ">=70") / 4 +SUMIF(K43:K43, ">=70") / 4 + SUMIF(F43:F43, ">1") / 4 + SUMIF(H43:H43, ">1") / 4 + SUMIF(J43:J43, ">1") / 4 + SUMIF(L43:L43, ">1") / 4 -> 0 | AL43: =SUMIF(M43:M43, ">=70") / 4 +SUMIF(O43:O43, ">=70") / 4 +SUMIF(Q43:Q43, ">=70") / 4 +SUMIF(S43:S43, ">=70") / 4 + SUMIF(N43:N43, ">1") / 4 + SUMIF(P43:P43, ">1") / 4 + SUMIF(R43:R43, ">1") / 4 + SUMIF(T43:T43, ">1") / 4 -> 0 | AM43: =SUMIF(U43:U43, ">=70") / 4 +SUMIF(W43:W43, ">=70") / 4 +SUMIF(Y43:Y43, ">=70") / 4 +SUMIF(AA43:AA43, ">=70") / 4 + SUMIF(V43:V43, ">1") / 4 + SUMIF(X43:X43, ">1") / 4 + SUMIF(Z43:Z43, ">1") / 4 + SUMIF(AB43:AB43, ">1") / 4 -> 0 | AN43: =SUMIF(AC43:AC43, ">=65") / 4 +SUMIF(AE43:AE43, ">=65") / 4 +SUMIF(AG43:AG43, ">=65") / 4 +SUMIF(AI43:AI43, ">=65") / 4 + SUMIF(AD43:AD43, ">1") / 4 + SUMIF(AF43:AF43, ">1") / 4 + SUMIF(AH43:AH43, ">1") / 4 + SUMIF(AJ43:AJ43, ">1") / 4 -> 0 | AO43: =AVERAGE(AK43:AN43) -> 0 | AR43: =IF(AO43<70, AO43*0.5, "") -> 0 | AT43: =AS43*50% -> 0 | AU43: =IF(AS43<>"", IF(AR43="","",AR43+AT43), "") | AV43: =IF(AU43 < 70, AR43*30%, "") | AX43: =AW43*70% -> 0 | AY43: =IF(AW43<>"", IF(AV43="", "", AV43+AX43), "") | AZ43: =IF(AND(AU43<70, AY43<70), AO43, "") | BB43: =IF(AW43<>"", IF(AY43>=70, AY43, IF(AZ43+BA43>=70, AZ43+BA43, "")), IF(AS43<>"", IF(AU43>=70, AU43, ""), IF(AO43>=70, AO43, ""))) | BC43: =IF(AW43<>"", IF(AY43<70, IF(AZ43+BA43<70, AZ43+BA43, ""), ""), IF(AS43<>"", IF(AU43<70, AU43, ""), IF(AO43<70, AO43, ""))) -> 0 | BE43: =SUMIF(E43:E43, ">=70") / 4 +SUMIF(F43:F43, ">1") / 4 +SUMIF(M43:M43, ">=70") / 4 +SUMIF(N43:N43, ">1") / 4 + SUMIF(U43:U43, ">=70") / 4 + SUMIF(V43:V43, ">1") / 4 + SUMIF(AC43:AC43, ">=70") / 4 + SUMIF(AD43:AD43, ">1") / 4 -> 0 | BF43: =SUMIF(G43:G43, ">=70") / 4 +SUMIF(H43:H43, ">1") / 4 +SUMIF(O43:O43, ">=70") / 4 +SUMIF(P43:P43, ">1") / 4 + SUMIF(W43:W43, ">=70") / 4 + SUMIF(X43:X43, ">1") / 4 + SUMIF(AE43:AE43, ">=70") / 4 + SUMIF(AF43:AF43, ">1") / 4 -> 0 | BG43: =SUMIF(I43:I43, ">=70") / 4 +SUMIF(J43:J43, ">1") / 4 +SUMIF(Q43:Q43, ">=70") / 4 +SUMIF(R43:R43, ">1") / 4 + SUMIF(Y43:Y43, ">=70") / 4 + SUMIF(Z43:Z43, ">1") / 4 + SUMIF(AG43:AG43, ">=70") / 4 + SUMIF(AH43:AH43, ">1") / 4 -> 0 | BH43: =SUMIF(K43:K43, ">=70") / 4 +SUMIF(L43:L43, ">1") / 4 +SUMIF(S43:S43, ">=70") / 4 +SUMIF(T43:T43, ">1") / 4 + SUMIF(AA43:AA43, ">=70") / 4 + SUMIF(AB43:AB43, ">1") / 4 + SUMIF(AI43:AI43, ">=70") / 4 + SUMIF(AJ43:AJ43, ">1") / 4 -> 0 | BI43: =AVERAGE(BE43:BH43) -> 0
A44: 34 | B44: 4A-D-34 | AK44: =SUMIF(E44:E44, ">=70") / 4 +SUMIF(G44:G44, ">=70") / 4 +SUMIF(I44:I44, ">=70") / 4 +SUMIF(K44:K44, ">=70") / 4 + SUMIF(F44:F44, ">1") / 4 + SUMIF(H44:H44, ">1") / 4 + SUMIF(J44:J44, ">1") / 4 + SUMIF(L44:L44, ">1") / 4 -> 0 | AL44: =SUMIF(M44:M44, ">=70") / 4 +SUMIF(O44:O44, ">=70") / 4 +SUMIF(Q44:Q44, ">=70") / 4 +SUMIF(S44:S44, ">=70") / 4 + SUMIF(N44:N44, ">1") / 4 + SUMIF(P44:P44, ">1") / 4 + SUMIF(R44:R44, ">1") / 4 + SUMIF(T44:T44, ">1") / 4 -> 0 | AM44: =SUMIF(U44:U44, ">=70") / 4 +SUMIF(W44:W44, ">=70") / 4 +SUMIF(Y44:Y44, ">=70") / 4 +SUMIF(AA44:AA44, ">=70") / 4 + SUMIF(V44:V44, ">1") / 4 + SUMIF(X44:X44, ">1") / 4 + SUMIF(Z44:Z44, ">1") / 4 + SUMIF(AB44:AB44, ">1") / 4 -> 0 | AN44: =SUMIF(AC44:AC44, ">=65") / 4 +SUMIF(AE44:AE44, ">=65") / 4 +SUMIF(AG44:AG44, ">=65") / 4 +SUMIF(AI44:AI44, ">=65") / 4 + SUMIF(AD44:AD44, ">1") / 4 + SUMIF(AF44:AF44, ">1") / 4 + SUMIF(AH44:AH44, ">1") / 4 + SUMIF(AJ44:AJ44, ">1") / 4 -> 0 | AO44: =AVERAGE(AK44:AN44) -> 0 | AR44: =IF(AO44<70, AO44*0.5, "") -> 0 | AT44: =AS44*50% -> 0 | AU44: =IF(AS44<>"", IF(AR44="","",AR44+AT44), "") | AV44: =IF(AU44 < 70, AR44*30%, "") | AX44: =AW44*70% -> 0 | AY44: =IF(AW44<>"", IF(AV44="", "", AV44+AX44), "") | AZ44: =IF(AND(AU44<70, AY44<70), AO44, "") | BB44: =IF(AW44<>"", IF(AY44>=70, AY44, IF(AZ44+BA44>=70, AZ44+BA44, "")), IF(AS44<>"", IF(AU44>=70, AU44, ""), IF(AO44>=70, AO44, ""))) | BC44: =IF(AW44<>"", IF(AY44<70, IF(AZ44+BA44<70, AZ44+BA44, ""), ""), IF(AS44<>"", IF(AU44<70, AU44, ""), IF(AO44<70, AO44, ""))) -> 0 | BE44: =SUMIF(E44:E44, ">=70") / 4 +SUMIF(F44:F44, ">1") / 4 +SUMIF(M44:M44, ">=70") / 4 +SUMIF(N44:N44, ">1") / 4 + SUMIF(U44:U44, ">=70") / 4 + SUMIF(V44:V44, ">1") / 4 + SUMIF(AC44:AC44, ">=70") / 4 + SUMIF(AD44:AD44, ">1") / 4 -> 0 | BF44: =SUMIF(G44:G44, ">=70") / 4 +SUMIF(H44:H44, ">1") / 4 +SUMIF(O44:O44, ">=70") / 4 +SUMIF(P44:P44, ">1") / 4 + SUMIF(W44:W44, ">=70") / 4 + SUMIF(X44:X44, ">1") / 4 + SUMIF(AE44:AE44, ">=70") / 4 + SUMIF(AF44:AF44, ">1") / 4 -> 0 | BG44: =SUMIF(I44:I44, ">=70") / 4 +SUMIF(J44:J44, ">1") / 4 +SUMIF(Q44:Q44, ">=70") / 4 +SUMIF(R44:R44, ">1") / 4 + SUMIF(Y44:Y44, ">=70") / 4 + SUMIF(Z44:Z44, ">1") / 4 + SUMIF(AG44:AG44, ">=70") / 4 + SUMIF(AH44:AH44, ">1") / 4 -> 0 | BH44: =SUMIF(K44:K44, ">=70") / 4 +SUMIF(L44:L44, ">1") / 4 +SUMIF(S44:S44, ">=70") / 4 +SUMIF(T44:T44, ">1") / 4 + SUMIF(AA44:AA44, ">=70") / 4 + SUMIF(AB44:AB44, ">1") / 4 + SUMIF(AI44:AI44, ">=70") / 4 + SUMIF(AJ44:AJ44, ">1") / 4 -> 0 | BI44: =AVERAGE(BE44:BH44) -> 0
A45: 35 | B45: 4A-D-35 | AK45: =SUMIF(E45:E45, ">=70") / 4 +SUMIF(G45:G45, ">=70") / 4 +SUMIF(I45:I45, ">=70") / 4 +SUMIF(K45:K45, ">=70") / 4 + SUMIF(F45:F45, ">1") / 4 + SUMIF(H45:H45, ">1") / 4 + SUMIF(J45:J45, ">1") / 4 + SUMIF(L45:L45, ">1") / 4 -> 0 | AL45: =SUMIF(M45:M45, ">=70") / 4 +SUMIF(O45:O45, ">=70") / 4 +SUMIF(Q45:Q45, ">=70") / 4 +SUMIF(S45:S45, ">=70") / 4 + SUMIF(N45:N45, ">1") / 4 + SUMIF(P45:P45, ">1") / 4 + SUMIF(R45:R45, ">1") / 4 + SUMIF(T45:T45, ">1") / 4 -> 0 | AM45: =SUMIF(U45:U45, ">=70") / 4 +SUMIF(W45:W45, ">=70") / 4 +SUMIF(Y45:Y45, ">=70") / 4 +SUMIF(AA45:AA45, ">=70") / 4 + SUMIF(V45:V45, ">1") / 4 + SUMIF(X45:X45, ">1") / 4 + SUMIF(Z45:Z45, ">1") / 4 + SUMIF(AB45:AB45, ">1") / 4 -> 0 | AN45: =SUMIF(AC45:AC45, ">=65") / 4 +SUMIF(AE45:AE45, ">=65") / 4 +SUMIF(AG45:AG45, ">=65") / 4 +SUMIF(AI45:AI45, ">=65") / 4 + SUMIF(AD45:AD45, ">1") / 4 + SUMIF(AF45:AF45, ">1") / 4 + SUMIF(AH45:AH45, ">1") / 4 + SUMIF(AJ45:AJ45, ">1") / 4 -> 0 | AO45: =AVERAGE(AK45:AN45) -> 0 | AR45: =IF(AO45<70, AO45*0.5, "") -> 0 | AT45: =AS45*50% -> 0 | AU45: =IF(AS45<>"", IF(AR45="","",AR45+AT45), "") | AV45: =IF(AU45 < 70, AR45*30%, "") | AX45: =AW45*70% -> 0 | AY45: =IF(AW45<>"", IF(AV45="", "", AV45+AX45), "") | AZ45: =IF(AND(AU45<70, AY45<70), AO45, "") | BB45: =IF(AW45<>"", IF(AY45>=70, AY45, IF(AZ45+BA45>=70, AZ45+BA45, "")), IF(AS45<>"", IF(AU45>=70, AU45, ""), IF(AO45>=70, AO45, ""))) | BC45: =IF(AW45<>"", IF(AY45<70, IF(AZ45+BA45<70, AZ45+BA45, ""), ""), IF(AS45<>"", IF(AU45<70, AU45, ""), IF(AO45<70, AO45, ""))) -> 0 | BE45: =SUMIF(E45:E45, ">=70") / 4 +SUMIF(F45:F45, ">1") / 4 +SUMIF(M45:M45, ">=70") / 4 +SUMIF(N45:N45, ">1") / 4 + SUMIF(U45:U45, ">=70") / 4 + SUMIF(V45:V45, ">1") / 4 + SUMIF(AC45:AC45, ">=70") / 4 + SUMIF(AD45:AD45, ">1") / 4 -> 0 | BF45: =SUMIF(G45:G45, ">=70") / 4 +SUMIF(H45:H45, ">1") / 4 +SUMIF(O45:O45, ">=70") / 4 +SUMIF(P45:P45, ">1") / 4 + SUMIF(W45:W45, ">=70") / 4 + SUMIF(X45:X45, ">1") / 4 + SUMIF(AE45:AE45, ">=70") / 4 + SUMIF(AF45:AF45, ">1") / 4 -> 0 | BG45: =SUMIF(I45:I45, ">=70") / 4 +SUMIF(J45:J45, ">1") / 4 +SUMIF(Q45:Q45, ">=70") / 4 +SUMIF(R45:R45, ">1") / 4 + SUMIF(Y45:Y45, ">=70") / 4 + SUMIF(Z45:Z45, ">1") / 4 + SUMIF(AG45:AG45, ">=70") / 4 + SUMIF(AH45:AH45, ">1") / 4 -> 0 | BH45: =SUMIF(K45:K45, ">=70") / 4 +SUMIF(L45:L45, ">1") / 4 +SUMIF(S45:S45, ">=70") / 4 +SUMIF(T45:T45, ">1") / 4 + SUMIF(AA45:AA45, ">=70") / 4 + SUMIF(AB45:AB45, ">1") / 4 + SUMIF(AI45:AI45, ">=70") / 4 + SUMIF(AJ45:AJ45, ">1") / 4 -> 0 | BI45: =AVERAGE(BE45:BH45) -> 0
A46: 36 | B46: 4A-D-36 | AK46: =SUMIF(E46:E46, ">=70") / 4 +SUMIF(G46:G46, ">=70") / 4 +SUMIF(I46:I46, ">=70") / 4 +SUMIF(K46:K46, ">=70") / 4 + SUMIF(F46:F46, ">1") / 4 + SUMIF(H46:H46, ">1") / 4 + SUMIF(J46:J46, ">1") / 4 + SUMIF(L46:L46, ">1") / 4 -> 0 | AL46: =SUMIF(M46:M46, ">=70") / 4 +SUMIF(O46:O46, ">=70") / 4 +SUMIF(Q46:Q46, ">=70") / 4 +SUMIF(S46:S46, ">=70") / 4 + SUMIF(N46:N46, ">1") / 4 + SUMIF(P46:P46, ">1") / 4 + SUMIF(R46:R46, ">1") / 4 + SUMIF(T46:T46, ">1") / 4 -> 0 | AM46: =SUMIF(U46:U46, ">=70") / 4 +SUMIF(W46:W46, ">=70") / 4 +SUMIF(Y46:Y46, ">=70") / 4 +SUMIF(AA46:AA46, ">=70") / 4 + SUMIF(V46:V46, ">1") / 4 + SUMIF(X46:X46, ">1") / 4 + SUMIF(Z46:Z46, ">1") / 4 + SUMIF(AB46:AB46, ">1") / 4 -> 0 | AN46: =SUMIF(AC46:AC46, ">=65") / 4 +SUMIF(AE46:AE46, ">=65") / 4 +SUMIF(AG46:AG46, ">=65") / 4 +SUMIF(AI46:AI46, ">=65") / 4 + SUMIF(AD46:AD46, ">1") / 4 + SUMIF(AF46:AF46, ">1") / 4 + SUMIF(AH46:AH46, ">1") / 4 + SUMIF(AJ46:AJ46, ">1") / 4 -> 0 | AO46: =AVERAGE(AK46:AN46) -> 0 | AR46: =IF(AO46<70, AO46*0.5, "") -> 0 | AT46: =AS46*50% -> 0 | AU46: =IF(AS46<>"", IF(AR46="","",AR46+AT46), "") | AV46: =IF(AU46 < 70, AR46*30%, "") | AX46: =AW46*70% -> 0 | AY46: =IF(AW46<>"", IF(AV46="", "", AV46+AX46), "") | AZ46: =IF(AND(AU46<70, AY46<70), AO46, "") | BB46: =IF(AW46<>"", IF(AY46>=70, AY46, IF(AZ46+BA46>=70, AZ46+BA46, "")), IF(AS46<>"", IF(AU46>=70, AU46, ""), IF(AO46>=70, AO46, ""))) | BC46: =IF(AW46<>"", IF(AY46<70, IF(AZ46+BA46<70, AZ46+BA46, ""), ""), IF(AS46<>"", IF(AU46<70, AU46, ""), IF(AO46<70, AO46, ""))) -> 0 | BE46: =SUMIF(E46:E46, ">=70") / 4 +SUMIF(F46:F46, ">1") / 4 +SUMIF(M46:M46, ">=70") / 4 +SUMIF(N46:N46, ">1") / 4 + SUMIF(U46:U46, ">=70") / 4 + SUMIF(V46:V46, ">1") / 4 + SUMIF(AC46:AC46, ">=70") / 4 + SUMIF(AD46:AD46, ">1") / 4 -> 0 | BF46: =SUMIF(G46:G46, ">=70") / 4 +SUMIF(H46:H46, ">1") / 4 +SUMIF(O46:O46, ">=70") / 4 +SUMIF(P46:P46, ">1") / 4 + SUMIF(W46:W46, ">=70") / 4 + SUMIF(X46:X46, ">1") / 4 + SUMIF(AE46:AE46, ">=70") / 4 + SUMIF(AF46:AF46, ">1") / 4 -> 0 | BG46: =SUMIF(I46:I46, ">=70") / 4 +SUMIF(J46:J46, ">1") / 4 +SUMIF(Q46:Q46, ">=70") / 4 +SUMIF(R46:R46, ">1") / 4 + SUMIF(Y46:Y46, ">=70") / 4 + SUMIF(Z46:Z46, ">1") / 4 + SUMIF(AG46:AG46, ">=70") / 4 + SUMIF(AH46:AH46, ">1") / 4 -> 0 | BH46: =SUMIF(K46:K46, ">=70") / 4 +SUMIF(L46:L46, ">1") / 4 +SUMIF(S46:S46, ">=70") / 4 +SUMIF(T46:T46, ">1") / 4 + SUMIF(AA46:AA46, ">=70") / 4 + SUMIF(AB46:AB46, ">1") / 4 + SUMIF(AI46:AI46, ">=70") / 4 + SUMIF(AJ46:AJ46, ">1") / 4 -> 0 | BI46: =AVERAGE(BE46:BH46) -> 0
A47: 37 | B47: 4A-D-37 | AK47: =SUMIF(E47:E47, ">=70") / 4 +SUMIF(G47:G47, ">=70") / 4 +SUMIF(I47:I47, ">=70") / 4 +SUMIF(K47:K47, ">=70") / 4 + SUMIF(F47:F47, ">1") / 4 + SUMIF(H47:H47, ">1") / 4 + SUMIF(J47:J47, ">1") / 4 + SUMIF(L47:L47, ">1") / 4 -> 0 | AL47: =SUMIF(M47:M47, ">=70") / 4 +SUMIF(O47:O47, ">=70") / 4 +SUMIF(Q47:Q47, ">=70") / 4 +SUMIF(S47:S47, ">=70") / 4 + SUMIF(N47:N47, ">1") / 4 + SUMIF(P47:P47, ">1") / 4 + SUMIF(R47:R47, ">1") / 4 + SUMIF(T47:T47, ">1") / 4 -> 0 | AM47: =SUMIF(U47:U47, ">=70") / 4 +SUMIF(W47:W47, ">=70") / 4 +SUMIF(Y47:Y47, ">=70") / 4 +SUMIF(AA47:AA47, ">=70") / 4 + SUMIF(V47:V47, ">1") / 4 + SUMIF(X47:X47, ">1") / 4 + SUMIF(Z47:Z47, ">1") / 4 + SUMIF(AB47:AB47, ">1") / 4 -> 0 | AN47: =SUMIF(AC47:AC47, ">=65") / 4 +SUMIF(AE47:AE47, ">=65") / 4 +SUMIF(AG47:AG47, ">=65") / 4 +SUMIF(AI47:AI47, ">=65") / 4 + SUMIF(AD47:AD47, ">1") / 4 + SUMIF(AF47:AF47, ">1") / 4 + SUMIF(AH47:AH47, ">1") / 4 + SUMIF(AJ47:AJ47, ">1") / 4 -> 0 | AO47: =AVERAGE(AK47:AN47) -> 0 | AR47: =IF(AO47<70, AO47*0.5, "") -> 0 | AT47: =AS47*50% -> 0 | AU47: =IF(AS47<>"", IF(AR47="","",AR47+AT47), "") | AV47: =IF(AU47 < 70, AR47*30%, "") | AX47: =AW47*70% -> 0 | AY47: =IF(AW47<>"", IF(AV47="", "", AV47+AX47), "") | AZ47: =IF(AND(AU47<70, AY47<70), AO47, "") | BB47: =IF(AW47<>"", IF(AY47>=70, AY47, IF(AZ47+BA47>=70, AZ47+BA47, "")), IF(AS47<>"", IF(AU47>=70, AU47, ""), IF(AO47>=70, AO47, ""))) | BC47: =IF(AW47<>"", IF(AY47<70, IF(AZ47+BA47<70, AZ47+BA47, ""), ""), IF(AS47<>"", IF(AU47<70, AU47, ""), IF(AO47<70, AO47, ""))) -> 0 | BE47: =SUMIF(E47:E47, ">=70") / 4 +SUMIF(F47:F47, ">1") / 4 +SUMIF(M47:M47, ">=70") / 4 +SUMIF(N47:N47, ">1") / 4 + SUMIF(U47:U47, ">=70") / 4 + SUMIF(V47:V47, ">1") / 4 + SUMIF(AC47:AC47, ">=70") / 4 + SUMIF(AD47:AD47, ">1") / 4 -> 0 | BF47: =SUMIF(G47:G47, ">=70") / 4 +SUMIF(H47:H47, ">1") / 4 +SUMIF(O47:O47, ">=70") / 4 +SUMIF(P47:P47, ">1") / 4 + SUMIF(W47:W47, ">=70") / 4 + SUMIF(X47:X47, ">1") / 4 + SUMIF(AE47:AE47, ">=70") / 4 + SUMIF(AF47:AF47, ">1") / 4 -> 0 | BG47: =SUMIF(I47:I47, ">=70") / 4 +SUMIF(J47:J47, ">1") / 4 +SUMIF(Q47:Q47, ">=70") / 4 +SUMIF(R47:R47, ">1") / 4 + SUMIF(Y47:Y47, ">=70") / 4 + SUMIF(Z47:Z47, ">1") / 4 + SUMIF(AG47:AG47, ">=70") / 4 + SUMIF(AH47:AH47, ">1") / 4 -> 0 | BH47: =SUMIF(K47:K47, ">=70") / 4 +SUMIF(L47:L47, ">1") / 4 +SUMIF(S47:S47, ">=70") / 4 +SUMIF(T47:T47, ">1") / 4 + SUMIF(AA47:AA47, ">=70") / 4 + SUMIF(AB47:AB47, ">1") / 4 + SUMIF(AI47:AI47, ">=70") / 4 + SUMIF(AJ47:AJ47, ">1") / 4 -> 0 | BI47: =AVERAGE(BE47:BH47) -> 0
A48: 38 | B48: 4A-D-38 | AK48: =SUMIF(E48:E48, ">=70") / 4 +SUMIF(G48:G48, ">=70") / 4 +SUMIF(I48:I48, ">=70") / 4 +SUMIF(K48:K48, ">=70") / 4 + SUMIF(F48:F48, ">1") / 4 + SUMIF(H48:H48, ">1") / 4 + SUMIF(J48:J48, ">1") / 4 + SUMIF(L48:L48, ">1") / 4 -> 0 | AL48: =SUMIF(M48:M48, ">=70") / 4 +SUMIF(O48:O48, ">=70") / 4 +SUMIF(Q48:Q48, ">=70") / 4 +SUMIF(S48:S48, ">=70") / 4 + SUMIF(N48:N48, ">1") / 4 + SUMIF(P48:P48, ">1") / 4 + SUMIF(R48:R48, ">1") / 4 + SUMIF(T48:T48, ">1") / 4 -> 0 | AM48: =SUMIF(U48:U48, ">=70") / 4 +SUMIF(W48:W48, ">=70") / 4 +SUMIF(Y48:Y48, ">=70") / 4 +SUMIF(AA48:AA48, ">=70") / 4 + SUMIF(V48:V48, ">1") / 4 + SUMIF(X48:X48, ">1") / 4 + SUMIF(Z48:Z48, ">1") / 4 + SUMIF(AB48:AB48, ">1") / 4 -> 0 | AN48: =SUMIF(AC48:AC48, ">=65") / 4 +SUMIF(AE48:AE48, ">=65") / 4 +SUMIF(AG48:AG48, ">=65") / 4 +SUMIF(AI48:AI48, ">=65") / 4 + SUMIF(AD48:AD48, ">1") / 4 + SUMIF(AF48:AF48, ">1") / 4 + SUMIF(AH48:AH48, ">1") / 4 + SUMIF(AJ48:AJ48, ">1") / 4 -> 0 | AO48: =AVERAGE(AK48:AN48) -> 0 | AR48: =IF(AO48<70, AO48*0.5, "") -> 0 | AT48: =AS48*50% -> 0 | AU48: =IF(AS48<>"", IF(AR48="","",AR48+AT48), "") | AV48: =IF(AU48 < 70, AR48*30%, "") | AX48: =AW48*70% -> 0 | AY48: =IF(AW48<>"", IF(AV48="", "", AV48+AX48), "") | AZ48: =IF(AND(AU48<70, AY48<70), AO48, "") | BB48: =IF(AW48<>"", IF(AY48>=70, AY48, IF(AZ48+BA48>=70, AZ48+BA48, "")), IF(AS48<>"", IF(AU48>=70, AU48, ""), IF(AO48>=70, AO48, ""))) | BC48: =IF(AW48<>"", IF(AY48<70, IF(AZ48+BA48<70, AZ48+BA48, ""), ""), IF(AS48<>"", IF(AU48<70, AU48, ""), IF(AO48<70, AO48, ""))) -> 0 | BE48: =SUMIF(E48:E48, ">=70") / 4 +SUMIF(F48:F48, ">1") / 4 +SUMIF(M48:M48, ">=70") / 4 +SUMIF(N48:N48, ">1") / 4 + SUMIF(U48:U48, ">=70") / 4 + SUMIF(V48:V48, ">1") / 4 + SUMIF(AC48:AC48, ">=70") / 4 + SUMIF(AD48:AD48, ">1") / 4 -> 0 | BF48: =SUMIF(G48:G48, ">=70") / 4 +SUMIF(H48:H48, ">1") / 4 +SUMIF(O48:O48, ">=70") / 4 +SUMIF(P48:P48, ">1") / 4 + SUMIF(W48:W48, ">=70") / 4 + SUMIF(X48:X48, ">1") / 4 + SUMIF(AE48:AE48, ">=70") / 4 + SUMIF(AF48:AF48, ">1") / 4 -> 0 | BG48: =SUMIF(I48:I48, ">=70") / 4 +SUMIF(J48:J48, ">1") / 4 +SUMIF(Q48:Q48, ">=70") / 4 +SUMIF(R48:R48, ">1") / 4 + SUMIF(Y48:Y48, ">=70") / 4 + SUMIF(Z48:Z48, ">1") / 4 + SUMIF(AG48:AG48, ">=70") / 4 + SUMIF(AH48:AH48, ">1") / 4 -> 0 | BH48: =SUMIF(K48:K48, ">=70") / 4 +SUMIF(L48:L48, ">1") / 4 +SUMIF(S48:S48, ">=70") / 4 +SUMIF(T48:T48, ">1") / 4 + SUMIF(AA48:AA48, ">=70") / 4 + SUMIF(AB48:AB48, ">1") / 4 + SUMIF(AI48:AI48, ">=70") / 4 + SUMIF(AJ48:AJ48, ">1") / 4 -> 0 | BI48: =AVERAGE(BE48:BH48) -> 0
A49: 39 | B49: 4A-D-39 | AK49: =SUMIF(E49:E49, ">=70") / 4 +SUMIF(G49:G49, ">=70") / 4 +SUMIF(I49:I49, ">=70") / 4 +SUMIF(K49:K49, ">=70") / 4 + SUMIF(F49:F49, ">1") / 4 + SUMIF(H49:H49, ">1") / 4 + SUMIF(J49:J49, ">1") / 4 + SUMIF(L49:L49, ">1") / 4 -> 0 | AL49: =SUMIF(M49:M49, ">=70") / 4 +SUMIF(O49:O49, ">=70") / 4 +SUMIF(Q49:Q49, ">=70") / 4 +SUMIF(S49:S49, ">=70") / 4 + SUMIF(N49:N49, ">1") / 4 + SUMIF(P49:P49, ">1") / 4 + SUMIF(R49:R49, ">1") / 4 + SUMIF(T49:T49, ">1") / 4 -> 0 | AM49: =SUMIF(U49:U49, ">=70") / 4 +SUMIF(W49:W49, ">=70") / 4 +SUMIF(Y49:Y49, ">=70") / 4 +SUMIF(AA49:AA49, ">=70") / 4 + SUMIF(V49:V49, ">1") / 4 + SUMIF(X49:X49, ">1") / 4 + SUMIF(Z49:Z49, ">1") / 4 + SUMIF(AB49:AB49, ">1") / 4 -> 0 | AN49: =SUMIF(AC49:AC49, ">=65") / 4 +SUMIF(AE49:AE49, ">=65") / 4 +SUMIF(AG49:AG49, ">=65") / 4 +SUMIF(AI49:AI49, ">=65") / 4 + SUMIF(AD49:AD49, ">1") / 4 + SUMIF(AF49:AF49, ">1") / 4 + SUMIF(AH49:AH49, ">1") / 4 + SUMIF(AJ49:AJ49, ">1") / 4 -> 0 | AO49: =AVERAGE(AK49:AN49) -> 0 | AR49: =IF(AO49<70, AO49*0.5, "") -> 0 | AT49: =AS49*50% -> 0 | AU49: =IF(AS49<>"", IF(AR49="","",AR49+AT49), "") | AV49: =IF(AU49 < 70, AR49*30%, "") | AX49: =AW49*70% -> 0 | AY49: =IF(AW49<>"", IF(AV49="", "", AV49+AX49), "") | AZ49: =IF(AND(AU49<70, AY49<70), AO49, "") | BB49: =IF(AW49<>"", IF(AY49>=70, AY49, IF(AZ49+BA49>=70, AZ49+BA49, "")), IF(AS49<>"", IF(AU49>=70, AU49, ""), IF(AO49>=70, AO49, ""))) | BC49: =IF(AW49<>"", IF(AY49<70, IF(AZ49+BA49<70, AZ49+BA49, ""), ""), IF(AS49<>"", IF(AU49<70, AU49, ""), IF(AO49<70, AO49, ""))) -> 0 | BE49: =SUMIF(E49:E49, ">=70") / 4 +SUMIF(F49:F49, ">1") / 4 +SUMIF(M49:M49, ">=70") / 4 +SUMIF(N49:N49, ">1") / 4 + SUMIF(U49:U49, ">=70") / 4 + SUMIF(V49:V49, ">1") / 4 + SUMIF(AC49:AC49, ">=70") / 4 + SUMIF(AD49:AD49, ">1") / 4 -> 0 | BF49: =SUMIF(G49:G49, ">=70") / 4 +SUMIF(H49:H49, ">1") / 4 +SUMIF(O49:O49, ">=70") / 4 +SUMIF(P49:P49, ">1") / 4 + SUMIF(W49:W49, ">=70") / 4 + SUMIF(X49:X49, ">1") / 4 + SUMIF(AE49:AE49, ">=70") / 4 + SUMIF(AF49:AF49, ">1") / 4 -> 0 | BG49: =SUMIF(I49:I49, ">=70") / 4 +SUMIF(J49:J49, ">1") / 4 +SUMIF(Q49:Q49, ">=70") / 4 +SUMIF(R49:R49, ">1") / 4 + SUMIF(Y49:Y49, ">=70") / 4 + SUMIF(Z49:Z49, ">1") / 4 + SUMIF(AG49:AG49, ">=70") / 4 + SUMIF(AH49:AH49, ">1") / 4 -> 0 | BH49: =SUMIF(K49:K49, ">=70") / 4 +SUMIF(L49:L49, ">1") / 4 +SUMIF(S49:S49, ">=70") / 4 +SUMIF(T49:T49, ">1") / 4 + SUMIF(AA49:AA49, ">=70") / 4 + SUMIF(AB49:AB49, ">1") / 4 + SUMIF(AI49:AI49, ">=70") / 4 + SUMIF(AJ49:AJ49, ">1") / 4 -> 0 | BI49: =AVERAGE(BE49:BH49) -> 0
